Workbook

Sheet 📊 داشبورد
B1: 📊 داشبورد الكنترول المالي الشامل – الحضانة ومركز التوحد
B3: ← اختر الشهر للعرض | D3: يناير | E3: 💡 غيّر الشهر في الخانة الصفراء — الداشبورد يتحدث تلقائياً
B5: ▶ 🎯 حاسبة التارجت – كم محتاج تجيب عشان تكسب؟
B6: 💸 إجمالي المصروفات (تشغيل + رواتب) | C6: =IFERROR(INDEX('💸 المصروفات'!D21:O21,MATCH($D$3,{"يناير","فبراير","مارس","أبريل","مايو","يونيو","يوليو","أغسطس","سبتمبر","أكتوبر","نوفمبر","ديسمبر"},0)),0) -> 25900 | F6: 🎯 التارجت المطلوب (بنسبة الربح المستهدفة) | G6: =IFERROR(IFERROR(INDEX('💸 المصروفات'!D21:O21,MATCH($D$3,{"يناير","فبراير","مارس","أبريل","مايو","يونيو","يوليو","أغسطس","سبتمبر","أكتوبر","نوفمبر","ديسمبر"},0)),0)/(1-'⚙️ الإعدادات'!C7),0) -> -130.15075 | J6: 📉 الفجوة (التارجت – المحصّل) | K6: =IFERROR(IFERROR(INDEX('💸 المصروفات'!D21:O21,MATCH($D$3,{"يناير","فبراير","مارس","أبريل","مايو","يونيو","يوليو","أغسطس","سبتمبر","أكتوبر","نوفمبر","ديسمبر"},0)),0)/(1-'⚙️ الإعدادات'!C7),0)-IFERROR(INDIRECT("'"&$D$3&"'!I104"),0) -> -130.15075
B8: ▶ عشان توصل للتارجت محتاج →
B9: 🏥 طفل حضانة | C9: =IFERROR(CEILING(IFERROR(IFERROR(INDEX('💸 المصروفات'!D21:O21,MATCH($D$3,{"يناير","فبراير","مارس","أبريل","مايو","يونيو","يوليو","أغسطس","سبتمبر","أكتوبر","نوفمبر","ديسمبر"},0)),0)/(1-'⚙️ الإعدادات'!C7),0)/'⚙️ الإعدادات'!C4,1),0) -> 0 | F9: 🏠 يوم استضافة | G9: =IFERROR(CEILING(IFERROR(IFERROR(INDEX('💸 المصروفات'!D21:O21,MATCH($D$3,{"يناير","فبراير","مارس","أبريل","مايو","يونيو","يوليو","أغسطس","سبتمبر","أكتوبر","نوفمبر","ديسمبر"},0)),0)/(1-'⚙️ الإعدادات'!C7),0)/'⚙️ الإعدادات'!C5,1),0) -> -2 | J9: 🩺 جلسة | K9: =IFERROR(CEILING(IFERROR(IFERROR(INDEX('💸 المصروفات'!D21:O21,MATCH($D$3,{"يناير","فبراير","مارس","أبريل","مايو","يونيو","يوليو","أغسطس","سبتمبر","أكتوبر","نوفمبر","ديسمبر"},0)),0)/(1-'⚙️ الإعدادات'!C7),0)/'⚙️ الإعدادات'!C6,1),0) -> -3
B11: ▶ 📊 أداء الشهر المختار
B12: 💰 إجمالي الفواتير (المستحق) | C12: =IFERROR(INDIRECT("'"&$D$3&"'!H104"),0) -> 175000 | F12: ✅ إجمالي المحصّل | G12: =IFERROR(INDIRECT("'"&$D$3&"'!I104"),0) -> 0 | J12: ❌ متأخرات غير محصّلة | K12: =IFERROR(INDIRECT("'"&$D$3&"'!J104"),0) -> 175000
B13: 💸 مصروفات تشغيلية | C13: =IFERROR(INDEX('💸 المصروفات'!D20:O20,MATCH($D$3,{"يناير","فبراير","مارس","أبريل","مايو","يونيو","يوليو","أغسطس","سبتمبر","أكتوبر","نوفمبر","ديسمبر"},0)),0) -> 25900 | F13: 👔 رواتب الشهر | G13: =IFERROR(INDEX('👔 الرواتب'!L15:W15,MATCH($D$3,{"يناير","فبراير","مارس","أبريل","مايو","يونيو","يوليو","أغسطس","سبتمبر","أكتوبر","نوفمبر","ديسمبر"},0)),0) -> 61950 | J13: 📊 نسبة التحصيل | K13: =IFERROR(IFERROR(INDIRECT("'"&$D$3&"'!I104"),0)/IFERROR(INDIRECT("'"&$D$3&"'!H104"),0),0) -> 0
B15: ▶ 🏷️ تفصيل الإيرادات حسب الخدمة
B16: الخدمة | F16: عدد الأطفال | J16: المحصّل (ج.م)
B17: 🏥 حضانة | F17: =IFERROR(COUNTIF(INDIRECT("'"&$D$3&"'!D4:D103"),"حضانة"),0) -> 50 | J17: =IFERROR(SUMIF(INDIRECT("'"&$D$3&"'!D4:D103"),"حضانة",INDIRECT("'"&$D$3&"'!I4:I103")),0) -> 0
B18: 🏠 استضافة | F18: =IFERROR(COUNTIF(INDIRECT("'"&$D$3&"'!D4:D103"),"استضافة"),0) -> 20 | J18: =IFERROR(SUMIF(INDIRECT("'"&$D$3&"'!D4:D103"),"استضافة",INDIRECT("'"&$D$3&"'!I4:I103")),0) -> 0
B19: 🩺 جلسة | F19: =IFERROR(COUNTIF(INDIRECT("'"&$D$3&"'!D4:D103"),"جلسة"),0) -> 30 | J19: =IFERROR(SUMIF(INDIRECT("'"&$D$3&"'!D4:D103"),"جلسة",INDIRECT("'"&$D$3&"'!I4:I103")),0) -> 0
B21: ▶ 📅 ملخص الـ 12 شهر
B22: الشهر | C22: المحصّل | D22: مصروفات+رواتب | E22: صافي الربح | F22: نسبة التحصيل | G22: الحالة
B23: يناير | C23: =IFERROR(يناير!I104,0) -> 0 | D23: =IFERROR('💸 المصروفات'!D21,0) -> 25900 | E23: =IFERROR(يناير!I104-'💸 المصروفات'!D21,0) -> -25900 | F23: =IFERROR(يناير!I104/يناير!H104,0) -> 0 | G23: =IF(E23=0,"—",IF(E23>0,"✅ ربح","❌ خسارة")) -> ❌ خسارة
B24: فبراير | C24: =IFERROR(فبراير!I104,0) -> 0 | D24: =IFERROR('💸 المصروفات'!E21,0) -> 81900 | E24: =IFERROR(فبراير!I104-'💸 المصروفات'!E21,0) -> -81900 | F24: =IFERROR(فبراير!I104/فبراير!H104,0) -> 0 | G24: =IF(E24=0,"—",IF(E24>0,"✅ ربح","❌ خسارة")) -> ❌ خسارة
B25: مارس | C25: =IFERROR(مارس!I104,0) -> 0 | D25: =IFERROR('💸 المصروفات'!F21,0) -> 29500 | E25: =IFERROR(مارس!I104-'💸 المصروفات'!F21,0) -> -29500 | F25: =IFERROR(مارس!I104/مارس!H104,0) -> 0 | G25: =IF(E25=0,"—",IF(E25>0,"✅ ربح","❌ خسارة")) -> ❌ خسارة
B26: أبريل | C26: =IFERROR(أبريل!I104,0) -> 0 | D26: =IFERROR('💸 المصروفات'!G21,0) -> 28250 | E26: =IFERROR(أبريل!I104-'💸 المصروفات'!G21,0) -> -28250 | F26: =IFERROR(أبريل!I104/أبريل!H104,0) -> 0 | G26: =IF(E26=0,"—",IF(E26>0,"✅ ربح","❌ خسارة")) -> ❌ خسارة
B27: مايو | C27: =IFERROR(مايو!I104,0) -> 0 | D27: =IFERROR('💸 المصروفات'!H21,0) -> 25900 | E27: =IFERROR(مايو!I104-'💸 المصروفات'!H21,0) -> -25900 | F27: =IFERROR(مايو!I104/مايو!H104,0) -> 0 | G27: =IF(E27=0,"—",IF(E27>0,"✅ ربح","❌ خسارة")) -> ❌ خسارة
B28: يونيو | C28: =IFERROR(يونيو!I104,0) -> 0 | D28: =IFERROR('💸 المصروفات'!I21,0) -> 25900 | E28: =IFERROR(يونيو!I104-'💸 المصروفات'!I21,0) -> -25900 | F28: =IFERROR(يونيو!I104/يونيو!H104,0) -> 0 | G28: =IF(E28=0,"—",IF(E28>0,"✅ ربح","❌ خسارة")) -> ❌ خسارة
B29: يوليو | C29: =IFERROR(يوليو!I104,0) -> 0 | D29: =IFERROR('💸 المصروفات'!J21,0) -> 87850 | E29: =IFERROR(يوليو!I104-'💸 المصروفات'!J21,0) -> -87850 | F29: =IFERROR(يوليو!I104/يوليو!H104,0) -> 0 | G29: =IF(E29=0,"—",IF(E29>0,"✅ ربح","❌ خسارة")) -> ❌ خسارة
B30: أغسطس | C30: =IFERROR(أغسطس!I104,0) -> 0 | D30: =IFERROR('💸 المصروفات'!K21,0) -> 25900 | E30: =IFERROR(أغسطس!I104-'💸 المصروفات'!K21,0) -> -25900 | F30: =IFERROR(أغسطس!I104/أغسطس!H104,0) -> 0 | G30: =IF(E30=0,"—",IF(E30>0,"✅ ربح","❌ خسارة")) -> ❌ خسارة
B31: سبتمبر | C31: =IFERROR(سبتمبر!I104,0) -> 0 | D31: =IFERROR('💸 المصروفات'!L21,0) -> 87850 | E31: =IFERROR(سبتمبر!I104-'💸 المصروفات'!L21,0) -> -87850 | F31: =IFERROR(سبتمبر!I104/سبتمبر!H104,0) -> 0 | G31: =IF(E31=0,"—",IF(E31>0,"✅ ربح","❌ خسارة")) -> ❌ خسارة
B32: أكتوبر | C32: =IFERROR(أكتوبر!I104,0) -> 0 | D32: =IFERROR('💸 المصروفات'!M21,0) -> 87850 | E32: =IFERROR(أكتوبر!I104-'💸 المصروفات'!M21,0) -> -87850 | F32: =IFERROR(أكتوبر!I104/أكتوبر!H104,0) -> 0 | G32: =IF(E32=0,"—",IF(E32>0,"✅ ربح","❌ خسارة")) -> ❌ خسارة
B33: نوفمبر | C33: =IFERROR(نوفمبر!I104,0) -> 0 | D33: =IFERROR('💸 المصروفات'!N21,0) -> 87850 | E33: =IFERROR(نوفمبر!I104-'💸 المصروفات'!N21,0) -> -87850 | F33: =IFERROR(نوفمبر!I104/نوفمبر!H104,0) -> 0 | G33: =IF(E33=0,"—",IF(E33>0,"✅ ربح","❌ خسارة")) -> ❌ خسارة
B34: ديسمبر | C34: =IFERROR(ديسمبر!I104,0) -> 0 | D34: =IFERROR('💸 المصروفات'!O21,0) -> 87850 | E34: =IFERROR(ديسمبر!I104-'💸 المصروفات'!O21,0) -> -87850 | F34: =IFERROR(ديسمبر!I104/ديسمبر!H104,0) -> 0 | G34: =IF(E34=0,"—",IF(E34>0,"✅ ربح","❌ خسارة")) -> ❌ خسارة
B35: إجمالي السنة | C35: =SUM(C23:C34) -> 0 | D35: ='💸 المصروفات'!D21+'💸 المصروفات'!E21+'💸 المصروفات'!F21+'💸 المصروفات'!G21+'💸 المصروفات'!H21+'💸 المصروفات'!I21+'💸 المصروفات'!J21+'💸 المصروفات'!K21+'💸 المصروفات'!L21+'💸 المصروفات'!M21+'💸 المصروفات'!N21+'💸 المصروفات'!O21 -> 682500 | E35: =C35-D35 -> -682500 | F35: =IFERROR(C35/(يناير!I104+فبراير!I104+مارس!I104+أبريل!I104+مايو!I104+يونيو!I104+يوليو!I104+أغسطس!I104+سبتمبر!I104+أكتوبر!I104+نوفمبر!I104+ديسمبر!I104),0) -> 0
B37: ▶ 🔔 تنبيهات ذكية
B38: هل وصلت للتارجت؟ | C38: =IF(IFERROR(INDIRECT("'"&$D$3&"'!I104"),0)>=IFERROR(IFERROR(INDEX('💸 المصروفات'!D21:O21,MATCH($D$3,{"يناير","فبراير","مارس","أبريل","مايو","يونيو","يوليو","أغسطس","سبتمبر","أكتوبر","نوفمبر","ديسمبر"},0)),0)/(1-'⚙️ الإعدادات'!C7),0),"✅ نعم! تجاوزت التارجت – ممتاز","❌ لسه محتاج "&TEXT(IFERROR(IFERROR(INDEX('💸 المصروفات'!D21:O21,MATCH($D$3,{"يناير","فبراير","مارس","أبريل","مايو","يونيو","يوليو","أغسطس","سبتمبر","أكتوبر","نوفمبر","ديسمبر"},0)),0)/(1-'⚙️ الإعدادات'!C7),0)-IFERROR(INDIRECT("'"&$D$3&"'!I104"),0),"#,##0")&" ج.م عشان توصل للتارجت") -> ✅ نعم! تجاوزت التارجت – ممتاز
B39: الوضع المالي للشهر | C39: =IF(IFERROR(INDIRECT("'"&$D$3&"'!I104"),0)-IFERROR(INDEX('💸 المصروفات'!D21:O21,MATCH($D$3,{"يناير","فبراير","مارس","أبريل","مايو","يونيو","يوليو","أغسطس","سبتمبر","أكتوبر","نوفمبر","ديسمبر"},0)),0)>0,"✅ ربح "&TEXT(IFERROR(INDIRECT("'"&$D$3&"'!I104"),0)-IFERROR(INDEX('💸 المصروفات'!D21:O21,MATCH($D$3,{"يناير","فبراير","مارس","أبريل","مايو","يونيو","يوليو","أغسطس","سبتمبر","أكتوبر","نوفمبر","ديسمبر"},0)),0),"#,##0")&" ج.م هذا الشهر","❌ خسارة "&TEXT(ABS(IFERROR(INDIRECT("'"&$D$3&"'!I104"),0)-IFERROR(INDEX('💸 المصروفات'!D21:O21,MATCH($D$3,{"يناير","فبراير","مارس","أبريل","مايو","يونيو","يوليو","أغسطس","سبتمبر","أكتوبر","نوفمبر","ديسمبر"},0)),0)),"#,##0")&" ج.م – المصروفات أكبر من الإيرادات") -> ❌ خسارة 25,900 ج.م – المصروفات أكبر من الإيرادات
B40: نسبة التحصيل | C40: =IF(IFERROR(INDIRECT("'"&$D$3&"'!I104"),0)/IFERROR(INDIRECT("'"&$D$3&"'!H104"),0)>=0.9,"✅ ممتاز – نسبة التحصيل "&TEXT(IFERROR(INDIRECT("'"&$D$3&"'!I104"),0)/IFERROR(INDIRECT("'"&$D$3&"'!H104"),0),"0%"),IF(IFERROR(INDIRECT("'"&$D$3&"'!I104"),0)/IFERROR(INDIRECT("'"&$D$3&"'!H104"),0)>=0.7,"⚠️ مقبول – نسبة "&TEXT(IFERROR(INDIRECT("'"&$D$3&"'!I104"),0)/IFERROR(INDIRECT("'"&$D$3&"'!H104"),0),"0%"),"❌ ضعيف – نسبة التحصيل "&TEXT(IFERROR(IFERROR(INDIRECT("'"&$D$3&"'!I104"),0)/IFERROR(INDIRECT("'"&$D$3&"'!H104"),0),0),"0%"))) -> ❌ ضعيف – نسبة التحصيل 0%
B41: متأخرات تحتاج متابعة | C41: =IFERROR(COUNTIF(INDIRECT("'"&$D$3&"'!K4:K103"),"❌ لم يُدفع"),0)&" طفل لم يسددوا – متأخرات إجمالية: "&TEXT(IFERROR(INDIRECT("'"&$D$3&"'!J104"),0),"#,##0")&" ج.م" -> 100 طفل لم يسددوا – متأخرات إجمالية: 175,000 ج.م

Sheet ⚙️ الإعدادات
B1: ⚙️ الإعدادات – أسعار الخدمات والأهداف المالية
B3: 💡 الخلايا الصفراء فقط قابلة للتعديل — غيّر الأسعار وكل الشيتات تتحدث تلقائياً
B4: الخدمة | C4: ⏱️ بالساعة (ج.م) | D4: 📅 باليوم (ج.م) | E4: 🗓️ بالشهر (ج.م)
B5: 🏫 حضانة | C5: 50 | D5: 200 | E5: 3500
B6: 🏠 استضافة | C6: 40 | D6: 150 | E6: 2500
B7: 🩺 جلسة علاج | C7: 200 | D7: 600
B9: ▶ أهداف الربحية والطاقة الاستيعابية
B10: نسبة الربح المستهدفة % | C10: 0.2
B11: أقصى طاقة استيعابية (طفل) | C11: 100
B12: عدد أيام العمل في الشهر
B13: عدد ساعات العمل في اليوم | C13: 8
B15: ▶ جدول مرجعي تلقائي – السعر اليومي والشهري المحسوب
B16: الخدمة | C16: ساعة × أيام/شهر × ساعات/يوم | D16: يوم × أيام/شهر | E16: شهر (مباشر)
B17: 🏫 حضانة | C17: =C5*C12*C13 -> 0 | D17: =D5*C12 -> 0 | E17: =E5 -> 3500
B18: 🏠 استضافة | C18: =C6*C12*C13 -> 0 | D18: =D6*C12 -> 0 | E18: =E6 -> 2500
B19: 🩺 جلسة علاج | C19: =C7*C12*C13 -> 0 | D19: =D7*C12 -> 0 | E19: =IF(E7=0,"—",E7) -> —
B21: 🔒 كلمة السر (لفك الحماية) | E21: 1234

Sheet 👶 بيانات الأطفال
B1: 👶 بيانات الأطفال – 100 طفل
B3: # | C3: اسم الطفل | D3: اسم ولي الأمر | E3: رقم هاتف ولي الأمر | F3: رقم هاتف الطفل/الطفلة | G3: الرقم القومي | H3: الخدمة | I3: الوحدة | J3: السعر (ج.م) | K3: تاريخ التسجيل | L3: ملاحظات
B4: 1 | C4: أحمد محمد | D4: ولي أمر 1 | E4: 01000000001 | G4: 20000000000000 | H4: حضانة | I4: شهر | J4: 3500
B5: 2 | C5: فاطمة علي | D5: ولي أمر 2 | E5: 01000000002 | G5: 20000000000000 | H5: حضانة | I5: شهر | J5: 3500
B6: 3 | C6: عمر خالد | D6: ولي أمر 3 | E6: 01000000003 | G6: 20000000000000 | H6: جلسة | I6: جلسة | J6: 800
B7: 4 | C7: نور السيد | D7: ولي أمر 4 | E7: 01000000004 | G7: 20000000000000 | H7: استضافة | I7: يوم | J7: 200
B8: 5 | C8: مريم إبراهيم | D8: ولي أمر 5 | E8: 01000000005 | G8: 20000000000000 | H8: حضانة | I8: شهر | J8: 3500
B9: 6 | C9: يوسف حسن | D9: ولي أمر 6 | E9: 01000000006 | G9: 20000000000000 | H9: جلسة | I9: جلسة | J9: 800
B10: 7 | C10: سارة أحمد | D10: ولي أمر 7 | E10: 01000000007 | G10: 20000000000000 | H10: حضانة | I10: شهر | J10: 3500
B11: 8 | C11: كريم محمود | D11: ولي أمر 8 | E11: 01000000008 | G11: 20000000000000 | H11: استضافة | I11: يوم | J11: 200
B12: 9 | C12: لينا طارق | D12: ولي أمر 9 | E12: 01000000009 | G12: 20000000000000 | H12: حضانة | I12: شهر | J12: 3500
B13: 10 | C13: جنى وليد | D13: ولي أمر 10 | E13: 01000000010 | G13: 20000000000001 | H13: جلسة | I13: جلسة | J13: 800
B14: 11 | C14: زياد عمر | D14: ولي أمر 11 | E14: 01000000011 | G14: 20000000000001 | H14: حضانة | I14: شهر | J14: 3500
B15: 12 | C15: ريم ناصر | D15: ولي أمر 12 | E15: 01000000012 | G15: 20000000000001 | H15: حضانة | I15: شهر | J15: 3500
... B103: 100 | C103: حسن علاء 100 | D103: ولي أمر 100 | E103: 01000000100 | G103: 20000000000010 | H103: جلسة | I103: جلسة | J103: 800
B104: إجمالي الأطفال المسجلين | L104: =COUNTA(C4:C103) -> 100

Sheet 👔 الرواتب
B1: 👔 شيت الرواتب – 11 موظف (10 موظفات + مدير)
B3: # | C3: الاسم | D3: الوظيفة | E3: الراتب الأساسي (ج.م) | F3: بدل سكن (ج.م) | G3: بدل مواصلات (ج.م) | H3: حوافز (ج.م) | I3: خصومات (ج.م) | J3: صافي الراتب (ج.م) | L3: يناير | M3: فبراير | N3: مارس | O3: أبريل | P3: مايو | Q3: يونيو | R3: يوليو | S3: أغسطس | T3: سبتمبر | U3: أكتوبر | V3: نوفمبر | W3: ديسمبر | X3: إجمالي السنة (ج.م)
B4: 1 | C4: مدير | D4: المدير | E4: 6000 | F4: 500 | G4: 300 | H4: 0 | I4: 0 | J4: =E4+F4+G4+H4-I4 -> 6800 | L4: =J4 -> 6800 | M4: =J4 -> 6800 | N4: =J4 -> 6800 | O4: =J4 -> 6800 | P4: =J4 -> 6800 | Q4: =J4 -> 6800 | R4: =J4 -> 6800 | S4: =J4 -> 6800 | T4: =J4 -> 6800 | U4: =J4 -> 6800 | V4: =J4 -> 6800 | W4: =J4 -> 6800 | X4: =SUM(L4:W4) -> 81600
B5: 2 | C5: موظفة 1 | D5: معلمة حضانة | E5: 5000 | F5: 300 | G5: 200 | H5: 0 | I5: 0 | J5: =E5+F5+G5+H5-I5 -> 5500 | L5: =J5 -> 5500 | M5: =J5 -> 5500 | N5: =J5 -> 5500 | O5: =J5 -> 5500 | P5: =J5 -> 5500 | Q5: =J5 -> 5500 | R5: =J5 -> 5500 | S5: =J5 -> 5500 | T5: =J5 -> 5500 | U5: =J5 -> 5500 | V5: =J5 -> 5500 | W5: =J5 -> 5500 | X5: =SUM(L5:W5) -> 66000
B6: 3 | C6: موظفة 2 | D6: معلمة حضانة | E6: 5000 | F6: 300 | G6: 200 | H6: 0 | I6: 0 | J6: =E6+F6+G6+H6-I6 -> 5500 | L6: =J6 -> 5500 | M6: =J6 -> 5500 | N6: =J6 -> 5500 | O6: =J6 -> 5500 | P6: =J6 -> 5500 | Q6: =J6 -> 5500 | R6: =J6 -> 5500 | S6: =J6 -> 5500 | T6: =J6 -> 5500 | U6: =J6 -> 5500 | V6: =J6 -> 5500 | W6: =J6 -> 5500 | X6: =SUM(L6:W6) -> 66000
B7: 4 | C7: موظفة 3 | D7: معلمة حضانة | E7: 5000 | F7: 300 | G7: 200 | H7: 0 | I7: 0 | J7: =E7+F7+G7+H7-I7 -> 5500 | L7: =J7 -> 5500 | M7: =J7 -> 5500 | N7: =J7 -> 5500 | O7: =J7 -> 5500 | P7: =J7 -> 5500 | Q7: =J7 -> 5500 | R7: =J7 -> 5500 | S7: =J7 -> 5500 | T7: =J7 -> 5500 | U7: =J7 -> 5500 | V7: =J7 -> 5500 | W7: =J7 -> 5500 | X7: =SUM(L7:W7) -> 66000
B8: 5 | C8: موظفة 4 | D8: معالجة توحد | E8: 8000 | F8: 500 | G8: 300 | H8: 0 | I8: 0 | J8: =E8+F8+G8+H8-I8 -> 8800 | L8: =J8 -> 8800 | M8: =J8 -> 8800 | N8: =J8 -> 8800 | O8: =J8 -> 8800 | P8: =J8 -> 8800 | Q8: =J8 -> 8800 | R8: =J8 -> 8800 | S8: =J8 -> 8800 | T8: =J8 -> 8800 | U8: =J8 -> 8800 | V8: =J8 -> 8800 | W8: =J8 -> 8800 | X8: =SUM(L8:W8) -> 105600
B9: 6 | C9: موظفة 5 | D9: معالجة توحد | E9: 8000 | F9: 500 | G9: 300 | H9: 0 | I9: 0 | J9: =E9+F9+G9+H9-I9 -> 8800 | L9: =J9 -> 8800 | M9: =J9 -> 8800 | N9: =J9 -> 8800 | O9: =J9 -> 8800 | P9: =J9 -> 8800 | Q9: =J9 -> 8800 | R9: =J9 -> 8800 | S9: =J9 -> 8800 | T9: =J9 -> 8800 | U9: =J9 -> 8800 | V9: =J9 -> 8800 | W9: =J9 -> 8800 | X9: =SUM(L9:W9) -> 105600
B10: 7 | C10: موظفة 6 | D10: أخصائية نفسية | E10: 7000 | F10: 500 | G10: 300 | H10: 0 | I10: 0 | J10: =E10+F10+G10+H10-I10 -> 7800 | L10: =J10 -> 7800 | M10: =J10 -> 7800 | N10: =J10 -> 7800 | O10: =J10 -> 7800 | P10: =J10 -> 7800 | Q10: =J10 -> 7800 | R10: =J10 -> 7800 | S10: =J10 -> 7800 | T10: =J10 -> 7800 | U10: =J10 -> 7800 | V10: =J10 -> 7800 | W10: =J10 -> 7800 | X10: =SUM(L10:W10) -> 93600
B11: 8 | C11: موظفة 7 | D11: موظفة إدارية | E11: 3500 | F11: 200 | G11: 150 | H11: 0 | I11: 0 | J11: =E11+F11+G11+H11-I11 -> 3850 | L11: =J11 -> 3850 | M11: =J11 -> 3850 | N11: =J11 -> 3850 | O11: =J11 -> 3850 | P11: =J11 -> 3850 | Q11: =J11 -> 3850 | R11: =J11 -> 3850 | S11: =J11 -> 3850 | T11: =J11 -> 3850 | U11: =J11 -> 3850 | V11: =J11 -> 3850 | W11: =J11 -> 3850 | X11: =SUM(L11:W11) -> 46200
B12: 9 | C12: موظفة 8 | D12: مساعدة معلمة | E12: 3000 | F12: 200 | G12: 150 | H12: 0 | I12: 0 | J12: =E12+F12+G12+H12-I12 -> 3350 | L12: =J12 -> 3350 | M12: =J12 -> 3350 | N12: =J12 -> 3350 | O12: =J12 -> 3350 | P12: =J12 -> 3350 | Q12: =J12 -> 3350 | R12: =J12 -> 3350 | S12: =J12 -> 3350 | T12: =J12 -> 3350 | U12: =J12 -> 3350 | V12: =J12 -> 3350 | W12: =J12 -> 3350 | X12: =SUM(L12:W12) -> 40200
B13: 10 | C13: موظفة 9 | D13: مساعدة معلمة | E13: 3000 | F13: 200 | G13: 150 | H13: 0 | I13: 0 | J13: =E13+F13+G13+H13-I13 -> 3350 | L13: =J13 -> 3350 | M13: =J13 -> 3350 | N13: =J13 -> 3350 | O13: =J13 -> 3350 | P13: =J13 -> 3350 | Q13: =J13 -> 3350 | R13: =J13 -> 3350 | S13: =J13 -> 3350 | T13: =J13 -> 3350 | U13: =J13 -> 3350 | V13: =J13 -> 3350 | W13: =J13 -> 3350 | X13: =SUM(L13:W13) -> 40200
B14: 11 | C14: موظفة 10 | D14: فراشة / خدمات | E14: 2500 | F14: 100 | G14: 100 | H14: 0 | I14: 0 | J14: =E14+F14+G14+H14-I14 -> 2700 | L14: =J14 -> 2700 | M14: =J14 -> 2700 | N14: =J14 -> 2700 | O14: =J14 -> 2700 | P14: =J14 -> 2700 | Q14: =J14 -> 2700 | R14: =J14 -> 2700 | S14: =J14 -> 2700 | T14: =J14 -> 2700 | U14: =J14 -> 2700 | V14: =J14 -> 2700 | W14: =J14 -> 2700 | X14: =SUM(L14:W14) -> 32400
B15: إجمالي الرواتب الشهرية | E15: =SUM(E4:E14) -> 56000 | F15: =SUM(F4:F14) -> 3600 | G15: =SUM(G4:G14) -> 2350 | H15: =SUM(H4:H14) -> 0 | I15: =SUM(I4:I14) -> 0 | J15: =SUM(J4:J14) -> 61950 | L15: =SUM(L4:L14) -> 61950 | M15: =SUM(M4:M14) -> 61950 | N15: =SUM(N4:N14) -> 61950 | O15: =SUM(O4:O14) -> 61950 | P15: =SUM(P4:P14) -> 61950 | Q15: =SUM(Q4:Q14) -> 61950 | R15: =SUM(R4:R14) -> 61950 | S15: =SUM(S4:S14) -> 61950 | ... W15: =SUM(W4:W14) -> 61950 | X15: =SUM(L15:W15) -> 743400
B17: 💡 الخلايا الصفراء في الأشهر: تقدر تغير مبلغ الراتب الفعلي المدفوع لأي موظف في أي شهر (الافتراضي = صافي الراتب)

Sheet 💸 المصروفات
B1: 💸 المصروفات التشغيلية – تفصيل شهري
B3: # | C3: بند المصروف | D3: يناير | E3: فبراير | F3: مارس | G3: أبريل | H3: مايو | I3: يونيو | J3: يوليو | K3: أغسطس | L3: سبتمبر | M3: أكتوبر | N3: نوفمبر | O3: ديسمبر | P3: إجمالي السنة (ج.م)
B4: 1 | C4: إيجار المبنى | D4: 15000 | E4: 15000 | F4: 15000 | G4: 15000 | H4: 15000 | I4: 15000 | J4: 15000 | K4: 15000 | L4: 15000 | M4: 15000 | N4: 15000 | O4: 15000 | P4: =SUM(D4:O4) -> 180000
B5: 2 | C5: فاتورة كهرباء | D5: 2000 | E5: 2000 | F5: 2000 | G5: 2000 | H5: 2000 | I5: 2000 | J5: 2000 | K5: 2000 | L5: 2000 | M5: 2000 | N5: 2000 | O5: 2000 | P5: =SUM(D5:O5) -> 24000
B6: 3 | C6: فاتورة مياه | D6: 500 | E6: 500 | F6: 500 | G6: 500 | H6: 500 | I6: 500 | J6: 500 | K6: 500 | L6: 500 | M6: 500 | N6: 500 | O6: 500 | P6: =SUM(D6:O6) -> 6000
B7: 4 | C7: إنترنت وتليفون | D7: 500 | E7: 500 | F7: 500 | G7: 500 | H7: 500 | I7: 500 | J7: 500 | K7: 500 | L7: 500 | M7: 500 | N7: 500 | O7: 500 | P7: =SUM(D7:O7) -> 6000
B8: 5 | C8: مواد تعليمية وقرطاسية | D8: 3000 | E8: 3000 | F8: 3000 | G8: 3000 | H8: 3000 | I8: 3000 | J8: 3000 | K8: 3000 | L8: 3000 | M8: 3000 | N8: 3000 | O8: 3000 | P8: =SUM(D8:O8) -> 36000
B9: 6 | C9: مواد طبية / أدوية إسعافات | D9: 800 | E9: 800 | F9: 800 | G9: 800 | H9: 800 | I9: 800 | J9: 800 | K9: 800 | L9: 800 | M9: 800 | N9: 800 | O9: 800 | P9: =SUM(D9:O9) -> 9600
B10: 7 | C10: تسويق وإعلان (سوشيال ميديا) | D10: 2000 | E10: 2000 | F10: 2000 | G10: 2000 | H10: 2000 | I10: 2000 | J10: 2000 | K10: 2000 | L10: 2000 | M10: 2000 | N10: 2000 | O10: 2000 | P10: =SUM(D10:O10) -> 24000
B11: 8 | C11: صيانة وإصلاحات | D11: 500 | E11: 500 | F11: 500 | G11: 500 | H11: 500 | I11: 500 | J11: 500 | K11: 500 | L11: 500 | M11: 500 | N11: 500 | O11: 500 | P11: =SUM(D11:O11) -> 6000
B12: 9 | C12: مواصلات ومشتريات | D12: 500 | E12: 500 | F12: 500 | G12: 500 | H12: 500 | I12: 500 | J12: 500 | K12: 500 | L12: 500 | M12: 500 | N12: 500 | O12: 500 | P12: =SUM(D12:O12) -> 6000
B13: 10 | C13: ضيافة وأدوات نظافة | D13: 600 | E13: 600 | F13: 600 | G13: 600 | H13: 600 | I13: 600 | J13: 600 | K13: 600 | L13: 600 | M13: 600 | N13: 600 | O13: 600 | P13: =SUM(D13:O13) -> 7200
B14: 11 | C14: متفرقات أخرى | D14: 500 | E14: 500 | F14: 500 | G14: 500 | H14: 500 | I14: 500 | J14: 500 | K14: 500 | L14: 500 | M14: 500 | N14: 500 | O14: 500 | P14: =SUM(D14:O14) -> 6000
B15: 12 | P15: =SUM(D15:O15) -> 0
B16: 13 | P16: =SUM(D16:O16) -> 0
B17: 14 | P17: =SUM(D17:O17) -> 0
B18: 15 | P18: =SUM(D18:O18) -> 0
B19: 16 | P19: =SUM(D19:O19) -> 0
B20: إجمالي المصروفات التشغيلية | D20: =SUM(D4:D19) -> 25900 | E20: =SUM(E4:E19) -> 25900 | F20: =SUM(F4:F19) -> 25900 | G20: =SUM(G4:G19) -> 25900 | H20: =SUM(H4:H19) -> 25900 | I20: =SUM(I4:I19) -> 25900 | J20: =SUM(J4:J19) -> 25900 | K20: =SUM(K4:K19) -> 25900 | ... O20: =SUM(O4:O19) -> 25900 | P20: =SUM(D20:O20) -> 310800
B21: إجمالي الكل (مصروفات + رواتب) | D21: =D20+'👔 الرواتب'!D15 -> 25900 | E21: =E20+'👔 الرواتب'!E15 -> 81900 | F21: =F20+'👔 الرواتب'!F15 -> 29500 | G21: =G20+'👔 الرواتب'!G15 -> 28250 | H21: =H20+'👔 الرواتب'!H15 -> 25900 | I21: =I20+'👔 الرواتب'!I15 -> 25900 | J21: =J20+'👔 الرواتب'!J15 -> 87850 | K21: =K20+'👔 الرواتب'!K15 -> 25900 | ... O21: =O20+'👔 الرواتب'!O15 -> 87850 | P21: =SUM(D21:O21) -> 682500
B23: 💡 الصف الأخير (الإجمالي الكل) = مصروفات تشغيلية + رواتب مجتمعة — هو اللي بيتحسب منه التارجت في الداشبورد

Sheet 📄 كشف حساب
B1: 📄 كشف حساب الطفل – من تاريخ التسجيل
B3: 💡 ابحث باسم الطفل (كامل أو جزء) · رقم هاتف الطفل · الرقم القومي · رقم هاتف ولي الأمر
B4: 🔍 اكتب هنا | K4: =IF(IFERROR(MATCH($D$4,'👶 بيانات الأطفال'!$C$4:$C$103,0),0)>0,IFERROR(MATCH($D$4,'👶 بيانات الأطفال'!$C$4:$C$103,0),0)+3,IF(IFERROR(MATCH($D$4,'👶 بيانات الأطفال'!$F$4:$F$103,0),0)>0,IFERROR(MATCH($D$4,'👶 بيانات الأطفال'!$F$4:$F$103,0),0)+3,IF(IFERROR(MATCH($D$4,'👶 بيانات الأطفال'!$G$4:$G$103,0),0)>0,IFERROR(MATCH($D$4,'👶 بيانات الأطفال'!$G$4:$G$103,0),0)+3,IF(IFERROR(MATCH($D$4,'👶 بيانات الأطفال'!$E$4:$E$103,0),0)>0,IFERROR(MATCH($D$4,'👶 بيانات الأطفال'!$E$4:$E$103,0),0)+3,IF(IFERROR(MATCH("*"&$D$4&"*",'👶 بيانات الأطفال'!$C$4:$C$103,0),0)>0,IFERROR(MATCH("*"&$D$4&"*",'👶 بيانات الأطفال'!$C$4:$C$103,0),0)+3,0))))) -> 4
B5: =IF($D$4=""," ⬆️ اكتب في خانة البحث أعلاه",IF($K$4=0," ❌ لم يُعثر على نتائج – تحقق من البيانات"," ✅ تم العثور على الطفل · رقم "&($K$4-3)&" في قاعدة البيانات")) -> ⬆️ اكتب في خانة البحث أعلاه | K5: =IF($K$4=0,0,IFERROR(MONTH(INDIRECT("'👶 بيانات الأطفال'!K"&$K$4)),1)) -> 1
B7: ▶ بيانات الطفل الكاملة
B8: 👶 اسم الطفل | C8: =IF($K$4=0,"—",IFERROR(INDIRECT("'👶 بيانات الأطفال'!C"&$K$4),"—")) -> أحمد محمد | F8: 👨‍👩‍👧 ولي الأمر | G8: =IF($K$4=0,"—",IFERROR(INDIRECT("'👶 بيانات الأطفال'!D"&$K$4),"—")) -> ولي أمر 1
B9: 📞 هاتف ولي الأمر | C9: =IF($K$4=0,"—",IFERROR(INDIRECT("'👶 بيانات الأطفال'!E"&$K$4),"—")) -> 01000000001 | F9: 📱 هاتف الطفل | G9: =IF($K$4=0,"—",IFERROR(INDIRECT("'👶 بيانات الأطفال'!F"&$K$4),"—")) -> 0
B10: 🪪 الرقم القومي | C10: =IF($K$4=0,"—",IFERROR(INDIRECT("'👶 بيانات الأطفال'!G"&$K$4),"—")) -> 20000000000000 | F10: 🏷️ الخدمة الأساسية | G10: =IF($K$4=0,"—",IFERROR(INDIRECT("'👶 بيانات الأطفال'!H"&$K$4),"—")) -> حضانة
B11: 💰 السعر الأساسي | C11: =IF($K$4=0,"—",IFERROR(INDIRECT("'👶 بيانات الأطفال'!J"&$K$4)&" ج.م","—")) -> 3500 ج.م | F11: 📅 تاريخ التسجيل | G11: =IF($K$4=0,"—",IFERROR(TEXT(INDIRECT("'👶 بيانات الأطفال'!K"&$K$4),"DD/MM/YYYY"),"—")) -> 00/01/1900
B12: 📝 ملاحظات | C12: =IF($K$4=0,"—",IFERROR(INDIRECT("'👶 بيانات الأطفال'!L"&$K$4),"—")) -> 0 | F12: =IF($K$4=0,"—",IFERROR(INDIRECT("'👶 بيانات الأطفال'!L"&$K$4),"—")) -> 0
B14: ▶ كشف الحساب التفصيلي – من تاريخ التسجيل
B15: الشهر | C15: الخدمة | D15: الوحدة | E15: الكمية | F15: السعر (ج.م) | G15: الإجمالي (ج.م) | H15: المدفوع (ج.م) | I15: الرصيد (ج.م) | J15: الحالة
B16: =IF($K$4=0,"—",IF(1<$K$5,"—","يناير")) -> يناير | C16: =IF($K$4=0,"",IF(1<$K$5,"",IFERROR(INDIRECT("'"&"يناير"&"'!D"&$K$4),0))) -> حضانة | D16: =IF($K$4=0,"",IF(1<$K$5,"",IFERROR(INDIRECT("'"&"يناير"&"'!E"&$K$4),0))) -> شهر | E16: =IF($K$4=0,"",IF(1<$K$5,"",IFERROR(INDIRECT("'"&"يناير"&"'!F"&$K$4),0))) -> 1 | F16: =IF($K$4=0,"",IF(1<$K$5,"",IFERROR(INDIRECT("'"&"يناير"&"'!G"&$K$4),0))) -> 3500 | G16: =IF($K$4=0,"",IF(1<$K$5,"",IFERROR(INDIRECT("'"&"يناير"&"'!H"&$K$4),0))) -> 3500 | H16: =IF($K$4=0,"",IF(1<$K$5,"",IFERROR(INDIRECT("'"&"يناير"&"'!I"&$K$4),0))) -> 0 | I16: =IF($K$4=0,"",IF(1<$K$5,"",IFERROR(INDIRECT("'"&"يناير"&"'!J"&$K$4),0))) -> 3500 | J16: =IF($K$4=0,"",IF(1<$K$5,"قبل التسجيل",IFERROR(INDIRECT("'"&"يناير"&"'!K"&$K$4),"—"))) -> ❌ لم يُدفع
B17: =IF($K$4=0,"—",IF(2<$K$5,"—","فبراير")) -> فبراير | C17: =IF($K$4=0,"",IF(2<$K$5,"",IFERROR(INDIRECT("'"&"فبراير"&"'!D"&$K$4),0))) -> حضانة | D17: =IF($K$4=0,"",IF(2<$K$5,"",IFERROR(INDIRECT("'"&"فبراير"&"'!E"&$K$4),0))) -> شهر | E17: =IF($K$4=0,"",IF(2<$K$5,"",IFERROR(INDIRECT("'"&"فبراير"&"'!F"&$K$4),0))) -> 1 | F17: =IF($K$4=0,"",IF(2<$K$5,"",IFERROR(INDIRECT("'"&"فبراير"&"'!G"&$K$4),0))) -> 3500 | G17: =IF($K$4=0,"",IF(2<$K$5,"",IFERROR(INDIRECT("'"&"فبراير"&"'!H"&$K$4),0))) -> 3500 | H17: =IF($K$4=0,"",IF(2<$K$5,"",IFERROR(INDIRECT("'"&"فبراير"&"'!I"&$K$4),0))) -> 0 | I17: =IF($K$4=0,"",IF(2<$K$5,"",IFERROR(INDIRECT("'"&"فبراير"&"'!J"&$K$4),0))) -> 3500 | J17: =IF($K$4=0,"",IF(2<$K$5,"قبل التسجيل",IFERROR(INDIRECT("'"&"فبراير"&"'!K"&$K$4),"—"))) -> ❌ لم يُدفع
B18: =IF($K$4=0,"—",IF(3<$K$5,"—","مارس")) -> مارس | C18: =IF($K$4=0,"",IF(3<$K$5,"",IFERROR(INDIRECT("'"&"مارس"&"'!D"&$K$4),0))) -> حضانة | D18: =IF($K$4=0,"",IF(3<$K$5,"",IFERROR(INDIRECT("'"&"مارس"&"'!E"&$K$4),0))) -> شهر | E18: =IF($K$4=0,"",IF(3<$K$5,"",IFERROR(INDIRECT("'"&"مارس"&"'!F"&$K$4),0))) -> 1 | F18: =IF($K$4=0,"",IF(3<$K$5,"",IFERROR(INDIRECT("'"&"مارس"&"'!G"&$K$4),0))) -> 3500 | G18: =IF($K$4=0,"",IF(3<$K$5,"",IFERROR(INDIRECT("'"&"مارس"&"'!H"&$K$4),0))) -> 3500 | H18: =IF($K$4=0,"",IF(3<$K$5,"",IFERROR(INDIRECT("'"&"مارس"&"'!I"&$K$4),0))) -> 0 | I18: =IF($K$4=0,"",IF(3<$K$5,"",IFERROR(INDIRECT("'"&"مارس"&"'!J"&$K$4),0))) -> 3500 | J18: =IF($K$4=0,"",IF(3<$K$5,"قبل التسجيل",IFERROR(INDIRECT("'"&"مارس"&"'!K"&$K$4),"—"))) -> ❌ لم يُدفع
B19: =IF($K$4=0,"—",IF(4<$K$5,"—","أبريل")) -> أبريل | C19: =IF($K$4=0,"",IF(4<$K$5,"",IFERROR(INDIRECT("'"&"أبريل"&"'!D"&$K$4),0))) -> حضانة | D19: =IF($K$4=0,"",IF(4<$K$5,"",IFERROR(INDIRECT("'"&"أبريل"&"'!E"&$K$4),0))) -> شهر | E19: =IF($K$4=0,"",IF(4<$K$5,"",IFERROR(INDIRECT("'"&"أبريل"&"'!F"&$K$4),0))) -> 1 | F19: =IF($K$4=0,"",IF(4<$K$5,"",IFERROR(INDIRECT("'"&"أبريل"&"'!G"&$K$4),0))) -> 3500 | G19: =IF($K$4=0,"",IF(4<$K$5,"",IFERROR(INDIRECT("'"&"أبريل"&"'!H"&$K$4),0))) -> 3500 | H19: =IF($K$4=0,"",IF(4<$K$5,"",IFERROR(INDIRECT("'"&"أبريل"&"'!I"&$K$4),0))) -> 0 | I19: =IF($K$4=0,"",IF(4<$K$5,"",IFERROR(INDIRECT("'"&"أبريل"&"'!J"&$K$4),0))) -> 3500 | J19: =IF($K$4=0,"",IF(4<$K$5,"قبل التسجيل",IFERROR(INDIRECT("'"&"أبريل"&"'!K"&$K$4),"—"))) -> ❌ لم يُدفع
B20: =IF($K$4=0,"—",IF(5<$K$5,"—","مايو")) -> مايو | C20: =IF($K$4=0,"",IF(5<$K$5,"",IFERROR(INDIRECT("'"&"مايو"&"'!D"&$K$4),0))) -> حضانة | D20: =IF($K$4=0,"",IF(5<$K$5,"",IFERROR(INDIRECT("'"&"مايو"&"'!E"&$K$4),0))) -> شهر | E20: =IF($K$4=0,"",IF(5<$K$5,"",IFERROR(INDIRECT("'"&"مايو"&"'!F"&$K$4),0))) -> 1 | F20: =IF($K$4=0,"",IF(5<$K$5,"",IFERROR(INDIRECT("'"&"مايو"&"'!G"&$K$4),0))) -> 3500 | G20: =IF($K$4=0,"",IF(5<$K$5,"",IFERROR(INDIRECT("'"&"مايو"&"'!H"&$K$4),0))) -> 3500 | H20: =IF($K$4=0,"",IF(5<$K$5,"",IFERROR(INDIRECT("'"&"مايو"&"'!I"&$K$4),0))) -> 0 | I20: =IF($K$4=0,"",IF(5<$K$5,"",IFERROR(INDIRECT("'"&"مايو"&"'!J"&$K$4),0))) -> 3500 | J20: =IF($K$4=0,"",IF(5<$K$5,"قبل التسجيل",IFERROR(INDIRECT("'"&"مايو"&"'!K"&$K$4),"—"))) -> ❌ لم يُدفع
B21: =IF($K$4=0,"—",IF(6<$K$5,"—","يونيو")) -> يونيو | C21: =IF($K$4=0,"",IF(6<$K$5,"",IFERROR(INDIRECT("'"&"يونيو"&"'!D"&$K$4),0))) -> حضانة | D21: =IF($K$4=0,"",IF(6<$K$5,"",IFERROR(INDIRECT("'"&"يونيو"&"'!E"&$K$4),0))) -> شهر | E21: =IF($K$4=0,"",IF(6<$K$5,"",IFERROR(INDIRECT("'"&"يونيو"&"'!F"&$K$4),0))) -> 1 | F21: =IF($K$4=0,"",IF(6<$K$5,"",IFERROR(INDIRECT("'"&"يونيو"&"'!G"&$K$4),0))) -> 3500 | G21: =IF($K$4=0,"",IF(6<$K$5,"",IFERROR(INDIRECT("'"&"يونيو"&"'!H"&$K$4),0))) -> 3500 | H21: =IF($K$4=0,"",IF(6<$K$5,"",IFERROR(INDIRECT("'"&"يونيو"&"'!I"&$K$4),0))) -> 0 | I21: =IF($K$4=0,"",IF(6<$K$5,"",IFERROR(INDIRECT("'"&"يونيو"&"'!J"&$K$4),0))) -> 3500 | J21: =IF($K$4=0,"",IF(6<$K$5,"قبل التسجيل",IFERROR(INDIRECT("'"&"يونيو"&"'!K"&$K$4),"—"))) -> ❌ لم يُدفع
B22: =IF($K$4=0,"—",IF(7<$K$5,"—","يوليو")) -> يوليو | C22: =IF($K$4=0,"",IF(7<$K$5,"",IFERROR(INDIRECT("'"&"يوليو"&"'!D"&$K$4),0))) -> حضانة | D22: =IF($K$4=0,"",IF(7<$K$5,"",IFERROR(INDIRECT("'"&"يوليو"&"'!E"&$K$4),0))) -> شهر | E22: =IF($K$4=0,"",IF(7<$K$5,"",IFERROR(INDIRECT("'"&"يوليو"&"'!F"&$K$4),0))) -> 1 | F22: =IF($K$4=0,"",IF(7<$K$5,"",IFERROR(INDIRECT("'"&"يوليو"&"'!G"&$K$4),0))) -> 3500 | G22: =IF($K$4=0,"",IF(7<$K$5,"",IFERROR(INDIRECT("'"&"يوليو"&"'!H"&$K$4),0))) -> 3500 | H22: =IF($K$4=0,"",IF(7<$K$5,"",IFERROR(INDIRECT("'"&"يوليو"&"'!I"&$K$4),0))) -> 0 | I22: =IF($K$4=0,"",IF(7<$K$5,"",IFERROR(INDIRECT("'"&"يوليو"&"'!J"&$K$4),0))) -> 3500 | J22: =IF($K$4=0,"",IF(7<$K$5,"قبل التسجيل",IFERROR(INDIRECT("'"&"يوليو"&"'!K"&$K$4),"—"))) -> ❌ لم يُدفع
B23: =IF($K$4=0,"—",IF(8<$K$5,"—","أغسطس")) -> أغسطس | C23: =IF($K$4=0,"",IF(8<$K$5,"",IFERROR(INDIRECT("'"&"أغسطس"&"'!D"&$K$4),0))) -> حضانة | D23: =IF($K$4=0,"",IF(8<$K$5,"",IFERROR(INDIRECT("'"&"أغسطس"&"'!E"&$K$4),0))) -> شهر | E23: =IF($K$4=0,"",IF(8<$K$5,"",IFERROR(INDIRECT("'"&"أغسطس"&"'!F"&$K$4),0))) -> 1 | F23: =IF($K$4=0,"",IF(8<$K$5,"",IFERROR(INDIRECT("'"&"أغسطس"&"'!G"&$K$4),0))) -> 3500 | G23: =IF($K$4=0,"",IF(8<$K$5,"",IFERROR(INDIRECT("'"&"أغسطس"&"'!H"&$K$4),0))) -> 3500 | H23: =IF($K$4=0,"",IF(8<$K$5,"",IFERROR(INDIRECT("'"&"أغسطس"&"'!I"&$K$4),0))) -> 0 | I23: =IF($K$4=0,"",IF(8<$K$5,"",IFERROR(INDIRECT("'"&"أغسطس"&"'!J"&$K$4),0))) -> 3500 | J23: =IF($K$4=0,"",IF(8<$K$5,"قبل التسجيل",IFERROR(INDIRECT("'"&"أغسطس"&"'!K"&$K$4),"—"))) -> ❌ لم يُدفع
B24: =IF($K$4=0,"—",IF(9<$K$5,"—","سبتمبر")) -> سبتمبر | C24: =IF($K$4=0,"",IF(9<$K$5,"",IFERROR(INDIRECT("'"&"سبتمبر"&"'!D"&$K$4),0))) -> حضانة | D24: =IF($K$4=0,"",IF(9<$K$5,"",IFERROR(INDIRECT("'"&"سبتمبر"&"'!E"&$K$4),0))) -> شهر | E24: =IF($K$4=0,"",IF(9<$K$5,"",IFERROR(INDIRECT("'"&"سبتمبر"&"'!F"&$K$4),0))) -> 1 | F24: =IF($K$4=0,"",IF(9<$K$5,"",IFERROR(INDIRECT("'"&"سبتمبر"&"'!G"&$K$4),0))) -> 3500 | G24: =IF($K$4=0,"",IF(9<$K$5,"",IFERROR(INDIRECT("'"&"سبتمبر"&"'!H"&$K$4),0))) -> 3500 | H24: =IF($K$4=0,"",IF(9<$K$5,"",IFERROR(INDIRECT("'"&"سبتمبر"&"'!I"&$K$4),0))) -> 0 | I24: =IF($K$4=0,"",IF(9<$K$5,"",IFERROR(INDIRECT("'"&"سبتمبر"&"'!J"&$K$4),0))) -> 3500 | J24: =IF($K$4=0,"",IF(9<$K$5,"قبل التسجيل",IFERROR(INDIRECT("'"&"سبتمبر"&"'!K"&$K$4),"—"))) -> ❌ لم يُدفع
B25: =IF($K$4=0,"—",IF(10<$K$5,"—","أكتوبر")) -> أكتوبر | C25: =IF($K$4=0,"",IF(10<$K$5,"",IFERROR(INDIRECT("'"&"أكتوبر"&"'!D"&$K$4),0))) -> حضانة | D25: =IF($K$4=0,"",IF(10<$K$5,"",IFERROR(INDIRECT("'"&"أكتوبر"&"'!E"&$K$4),0))) -> شهر | E25: =IF($K$4=0,"",IF(10<$K$5,"",IFERROR(INDIRECT("'"&"أكتوبر"&"'!F"&$K$4),0))) -> 1 | F25: =IF($K$4=0,"",IF(10<$K$5,"",IFERROR(INDIRECT("'"&"أكتوبر"&"'!G"&$K$4),0))) -> 3500 | G25: =IF($K$4=0,"",IF(10<$K$5,"",IFERROR(INDIRECT("'"&"أكتوبر"&"'!H"&$K$4),0))) -> 3500 | H25: =IF($K$4=0,"",IF(10<$K$5,"",IFERROR(INDIRECT("'"&"أكتوبر"&"'!I"&$K$4),0))) -> 0 | I25: =IF($K$4=0,"",IF(10<$K$5,"",IFERROR(INDIRECT("'"&"أكتوبر"&"'!J"&$K$4),0))) -> 3500 | J25: =IF($K$4=0,"",IF(10<$K$5,"قبل التسجيل",IFERROR(INDIRECT("'"&"أكتوبر"&"'!K"&$K$4),"—"))) -> ❌ لم يُدفع
B26: =IF($K$4=0,"—",IF(11<$K$5,"—","نوفمبر")) -> نوفمبر | C26: =IF($K$4=0,"",IF(11<$K$5,"",IFERROR(INDIRECT("'"&"نوفمبر"&"'!D"&$K$4),0))) -> حضانة | D26: =IF($K$4=0,"",IF(11<$K$5,"",IFERROR(INDIRECT("'"&"نوفمبر"&"'!E"&$K$4),0))) -> شهر | E26: =IF($K$4=0,"",IF(11<$K$5,"",IFERROR(INDIRECT("'"&"نوفمبر"&"'!F"&$K$4),0))) -> 1 | F26: =IF($K$4=0,"",IF(11<$K$5,"",IFERROR(INDIRECT("'"&"نوفمبر"&"'!G"&$K$4),0))) -> 3500 | G26: =IF($K$4=0,"",IF(11<$K$5,"",IFERROR(INDIRECT("'"&"نوفمبر"&"'!H"&$K$4),0))) -> 3500 | H26: =IF($K$4=0,"",IF(11<$K$5,"",IFERROR(INDIRECT("'"&"نوفمبر"&"'!I"&$K$4),0))) -> 0 | I26: =IF($K$4=0,"",IF(11<$K$5,"",IFERROR(INDIRECT("'"&"نوفمبر"&"'!J"&$K$4),0))) -> 3500 | J26: =IF($K$4=0,"",IF(11<$K$5,"قبل التسجيل",IFERROR(INDIRECT("'"&"نوفمبر"&"'!K"&$K$4),"—"))) -> ❌ لم يُدفع
B27: =IF($K$4=0,"—",IF(12<$K$5,"—","ديسمبر")) -> ديسمبر | C27: =IF($K$4=0,"",IF(12<$K$5,"",IFERROR(INDIRECT("'"&"ديسمبر"&"'!D"&$K$4),0))) -> حضانة | D27: =IF($K$4=0,"",IF(12<$K$5,"",IFERROR(INDIRECT("'"&"ديسمبر"&"'!E"&$K$4),0))) -> شهر | E27: =IF($K$4=0,"",IF(12<$K$5,"",IFERROR(INDIRECT("'"&"ديسمبر"&"'!F"&$K$4),0))) -> 1 | F27: =IF($K$4=0,"",IF(12<$K$5,"",IFERROR(INDIRECT("'"&"ديسمبر"&"'!G"&$K$4),0))) -> 3500 | G27: =IF($K$4=0,"",IF(12<$K$5,"",IFERROR(INDIRECT("'"&"ديسمبر"&"'!H"&$K$4),0))) -> 3500 | H27: =IF($K$4=0,"",IF(12<$K$5,"",IFERROR(INDIRECT("'"&"ديسمبر"&"'!I"&$K$4),0))) -> 0 | I27: =IF($K$4=0,"",IF(12<$K$5,"",IFERROR(INDIRECT("'"&"ديسمبر"&"'!J"&$K$4),0))) -> 3500 | J27: =IF($K$4=0,"",IF(12<$K$5,"قبل التسجيل",IFERROR(INDIRECT("'"&"ديسمبر"&"'!K"&$K$4),"—"))) -> ❌ لم يُدفع
B29: =IF($K$4=0,"—"," إجمالي من تاريخ التسجيل") -> إجمالي من تاريخ التسجيل | G29: =IF($K$4=0,"—",IF(1>=$K$5,IFERROR(INDIRECT("'"&"يناير"&"'!H"&$K$4),0),0)+IF(2>=$K$5,IFERROR(INDIRECT("'"&"فبراير"&"'!H"&$K$4),0),0)+IF(3>=$K$5,IFERROR(INDIRECT("'"&"مارس"&"'!H"&$K$4),0),0)+IF(4>=$K$5,IFERROR(INDIRECT("'"&"أبريل"&"'!H"&$K$4),0),0)+IF(5>=$K$5,IFERROR(INDIRECT("'"&"مايو"&"'!H"&$K$4),0),0)+IF(6>=$K$5,IFERROR(INDIRECT("'"&"يونيو"&"'!H"&$K$4),0),0)+IF(7>=$K$5,IFERROR(INDIRECT("'"&"يوليو"&"'!H"&$K$4),0),0)+IF(8>=$K$5,IFERROR(INDIRECT("'"&"أغسطس"&"'!H"&$K$4),0),0)+IF(9>=$K$5,IFERROR(INDIRECT("'"&"سبتمبر"&"'!H"&$K$4),0),0)+IF(10>=$K$5,IFERROR(INDIRECT("'"&"أكتوبر"&"'!H"&$K$4),0),0)+IF(11>=$K$5,IFERROR(INDIRECT("'"&"نوفمبر"&"'!H"&$K$4),0),0)+IF(12>=$K$5,IFERROR(INDIRECT("'"&"ديسمبر"&"'!H"&$K$4),0),0)) -> 42000 | H29: =IF($K$4=0,"—",IF(1>=$K$5,IFERROR(INDIRECT("'"&"يناير"&"'!I"&$K$4),0),0)+IF(2>=$K$5,IFERROR(INDIRECT("'"&"فبراير"&"'!I"&$K$4),0),0)+IF(3>=$K$5,IFERROR(INDIRECT("'"&"مارس"&"'!I"&$K$4),0),0)+IF(4>=$K$5,IFERROR(INDIRECT("'"&"أبريل"&"'!I"&$K$4),0),0)+IF(5>=$K$5,IFERROR(INDIRECT("'"&"مايو"&"'!I"&$K$4),0),0)+IF(6>=$K$5,IFERROR(INDIRECT("'"&"يونيو"&"'!I"&$K$4),0),0)+IF(7>=$K$5,IFERROR(INDIRECT("'"&"يوليو"&"'!I"&$K$4),0),0)+IF(8>=$K$5,IFERROR(INDIRECT("'"&"أغسطس"&"'!I"&$K$4),0),0)+IF(9>=$K$5,IFERROR(INDIRECT("'"&"سبتمبر"&"'!I"&$K$4),0),0)+IF(10>=$K$5,IFERROR(INDIRECT("'"&"أكتوبر"&"'!I"&$K$4),0),0)+IF(11>=$K$5,IFERROR(INDIRECT("'"&"نوفمبر"&"'!I"&$K$4),0),0)+IF(12>=$K$5,IFERROR(INDIRECT("'"&"ديسمبر"&"'!I"&$K$4),0),0)) -> 0 | I29: =IF($K$4=0,"—",IF(1>=$K$5,IFERROR(INDIRECT("'"&"يناير"&"'!J"&$K$4),0),0)+IF(2>=$K$5,IFERROR(INDIRECT("'"&"فبراير"&"'!J"&$K$4),0),0)+IF(3>=$K$5,IFERROR(INDIRECT("'"&"مارس"&"'!J"&$K$4),0),0)+IF(4>=$K$5,IFERROR(INDIRECT("'"&"أبريل"&"'!J"&$K$4),0),0)+IF(5>=$K$5,IFERROR(INDIRECT("'"&"مايو"&"'!J"&$K$4),0),0)+IF(6>=$K$5,IFERROR(INDIRECT("'"&"يونيو"&"'!J"&$K$4),0),0)+IF(7>=$K$5,IFERROR(INDIRECT("'"&"يوليو"&"'!J"&$K$4),0),0)+IF(8>=$K$5,IFERROR(INDIRECT("'"&"أغسطس"&"'!J"&$K$4),0),0)+IF(9>=$K$5,IFERROR(INDIRECT("'"&"سبتمبر"&"'!J"&$K$4),0),0)+IF(10>=$K$5,IFERROR(INDIRECT("'"&"أكتوبر"&"'!J"&$K$4),0),0)+IF(11>=$K$5,IFERROR(INDIRECT("'"&"نوفمبر"&"'!J"&$K$4),0),0)+IF(12>=$K$5,IFERROR(INDIRECT("'"&"ديسمبر"&"'!J"&$K$4),0),0)) -> 42000 | J29: =IF($K$4=0,"—",IF(I29=0,"✅ حساب صافٍ",IF(I29<0,"❌ خسارة: "&TEXT(ABS(I29),"#,##0")&" ج.م","⚠️ متأخر: "&TEXT(I29,"#,##0")&" ج.م"))) -> ⚠️ متأخر: 42,000 ج.م
B31: =IF($K$4=0,"—","شهور نشطة: "&($K$5>0)*(12-$K$5+1)&" شهر") -> شهور نشطة: 12 شهر | E31: =IF($K$4=0,"—","مدفوع: "&(IF(1>=$K$5,IF(IFERROR(INDIRECT("'"&"يناير"&"'!K"&$K$4),"")="✅ مدفوع",1,0),0)+IF(2>=$K$5,IF(IFERROR(INDIRECT("'"&"فبراير"&"'!K"&$K$4),"")="✅ مدفوع",1,0),0)+IF(3>=$K$5,IF(IFERROR(INDIRECT("'"&"مارس"&"'!K"&$K$4),"")="✅ مدفوع",1,0),0)+IF(4>=$K$5,IF(IFERROR(INDIRECT("'"&"أبريل"&"'!K"&$K$4),"")="✅ مدفوع",1,0),0)+IF(5>=$K$5,IF(IFERROR(INDIRECT("'"&"مايو"&"'!K"&$K$4),"")="✅ مدفوع",1,0),0)+IF(6>=$K$5,IF(IFERROR(INDIRECT("'"&"يونيو"&"'!K"&$K$4),"")="✅ مدفوع",1,0),0)+IF(7>=$K$5,IF(IFERROR(INDIRECT("'"&"يوليو"&"'!K"&$K$4),"")="✅ مدفوع",1,0),0)+IF(8>=$K$5,IF(IFERROR(INDIRECT("'"&"أغسطس"&"'!K"&$K$4),"")="✅ مدفوع",1,0),0)+IF(9>=$K$5,IF(IFERROR(INDIRECT("'"&"سبتمبر"&"'!K"&$K$4),"")="✅ مدفوع",1,0),0)+IF(10>=$K$5,IF(IFERROR(INDIRECT("'"&"أكتوبر"&"'!K"&$K$4),"")="✅ مدفوع",1,0),0)+IF(11>=$K$5,IF(IFERROR(INDIRECT("'"&"نوفمبر"&"'!K"&$K$4),"")="✅ مدفوع",1,0),0)+IF(12>=$K$5,IF(IFERROR(INDIRECT("'"&"ديسمبر"&"'!K"&$K$4),"")="✅ مدفوع",1,0),0))&" شهر") -> مدفوع: 0 شهر | H31: =IF($K$4=0,"—","متأخر: "&(IF(1>=$K$5,IF(IFERROR(INDIRECT("'"&"يناير"&"'!K"&$K$4),"")="❌ لم يُدفع",1,0),0)+IF(2>=$K$5,IF(IFERROR(INDIRECT("'"&"فبراير"&"'!K"&$K$4),"")="❌ لم يُدفع",1,0),0)+IF(3>=$K$5,IF(IFERROR(INDIRECT("'"&"مارس"&"'!K"&$K$4),"")="❌ لم يُدفع",1,0),0)+IF(4>=$K$5,IF(IFERROR(INDIRECT("'"&"أبريل"&"'!K"&$K$4),"")="❌ لم يُدفع",1,0),0)+IF(5>=$K$5,IF(IFERROR(INDIRECT("'"&"مايو"&"'!K"&$K$4),"")="❌ لم يُدفع",1,0),0)+IF(6>=$K$5,IF(IFERROR(INDIRECT("'"&"يونيو"&"'!K"&$K$4),"")="❌ لم يُدفع",1,0),0)+IF(7>=$K$5,IF(IFERROR(INDIRECT("'"&"يوليو"&"'!K"&$K$4),"")="❌ لم يُدفع",1,0),0)+IF(8>=$K$5,IF(IFERROR(INDIRECT("'"&"أغسطس"&"'!K"&$K$4),"")="❌ لم يُدفع",1,0),0)+IF(9>=$K$5,IF(IFERROR(INDIRECT("'"&"سبتمبر"&"'!K"&$K$4),"")="❌ لم يُدفع",1,0),0)+IF(10>=$K$5,IF(IFERROR(INDIRECT("'"&"أكتوبر"&"'!K"&$K$4),"")="❌ لم يُدفع",1,0),0)+IF(11>=$K$5,IF(IFERROR(INDIRECT("'"&"نوفمبر"&"'!K"&$K$4),"")="❌ لم يُدفع",1,0),0)+IF(12>=$K$5,IF(IFERROR(INDIRECT("'"&"ديسمبر"&"'!K"&$K$4),"")="❌ لم يُدفع",1,0),0))&" شهر") -> متأخر: 12 شهر

Sheet 🎯 تخطيط التارجت
B1: 🎯 تخطيط التارجت الشهري – اعرف المطلوب قبل ما تبدأ الشهر
B3: 💡 حدّد نسبة الربح المستهدفة لكل شهر في الخانات الصفراء — التارجت والاقتراحات بتتحسب تلقائياً
B5: الشهر | C5: إجمالي المصروفات (مصروفات+رواتب) | D5: نسبة الربح المستهدفة % | E5: التارجت المطلوب (ج.م) | F5: المحصّل الفعلي (ج.م) | G5: الفجوة (ج.م) | H5: الحالة
B6: يناير | C6: =IFERROR('💸 المصروفات'!D21,0) -> 25900 | D6: 0.2 | E6: =IFERROR(D6/(1-E6),D6) -> 0.2 | F6: =IFERROR(يناير!I104,0) -> 0 | G6: =E6-F6 -> 0.2 | H6: =IF(F6=0,"— لم يبدأ",IF(F6>=E6,"✅ تجاوزت التارجت",IF(F6>=E6*0.8,"⚠️ قريب ("&TEXT(F6/E6,"0%")&")","❌ بعيد ("&TEXT(F6/E6,"0%")&")"))) -> — لم يبدأ
B7: فبراير | C7: =IFERROR('💸 المصروفات'!E21,0) -> 81900 | D7: 0.2 | E7: =IFERROR(D7/(1-E7),D7) -> 0.2 | F7: =IFERROR(فبراير!I104,0) -> 0 | G7: =E7-F7 -> 0.2 | H7: =IF(F7=0,"— لم يبدأ",IF(F7>=E7,"✅ تجاوزت التارجت",IF(F7>=E7*0.8,"⚠️ قريب ("&TEXT(F7/E7,"0%")&")","❌ بعيد ("&TEXT(F7/E7,"0%")&")"))) -> — لم يبدأ
B8: مارس | C8: =IFERROR('💸 المصروفات'!F21,0) -> 29500 | D8: 0.2 | E8: =IFERROR(D8/(1-E8),D8) -> 0.2 | F8: =IFERROR(مارس!I104,0) -> 0 | G8: =E8-F8 -> 0.2 | H8: =IF(F8=0,"— لم يبدأ",IF(F8>=E8,"✅ تجاوزت التارجت",IF(F8>=E8*0.8,"⚠️ قريب ("&TEXT(F8/E8,"0%")&")","❌ بعيد ("&TEXT(F8/E8,"0%")&")"))) -> — لم يبدأ
B9: أبريل | C9: =IFERROR('💸 المصروفات'!G21,0) -> 28250 | D9: 0.2 | E9: =IFERROR(D9/(1-E9),D9) -> 0.2 | F9: =IFERROR(أبريل!I104,0) -> 0 | G9: =E9-F9 -> 0.2 | H9: =IF(F9=0,"— لم يبدأ",IF(F9>=E9,"✅ تجاوزت التارجت",IF(F9>=E9*0.8,"⚠️ قريب ("&TEXT(F9/E9,"0%")&")","❌ بعيد ("&TEXT(F9/E9,"0%")&")"))) -> — لم يبدأ
B10: مايو | C10: =IFERROR('💸 المصروفات'!H21,0) -> 25900 | D10: 0.2 | E10: =IFERROR(D10/(1-E10),D10) -> 0.2 | F10: =IFERROR(مايو!I104,0) -> 0 | G10: =E10-F10 -> 0.2 | H10: =IF(F10=0,"— لم يبدأ",IF(F10>=E10,"✅ تجاوزت التارجت",IF(F10>=E10*0.8,"⚠️ قريب ("&TEXT(F10/E10,"0%")&")","❌ بعيد ("&TEXT(F10/E10,"0%")&")"))) -> — لم يبدأ
B11: يونيو | C11: =IFERROR('💸 المصروفات'!I21,0) -> 25900 | D11: 0.2 | E11: =IFERROR(D11/(1-E11),D11) -> 0.2 | F11: =IFERROR(يونيو!I104,0) -> 0 | G11: =E11-F11 -> 0.2 | H11: =IF(F11=0,"— لم يبدأ",IF(F11>=E11,"✅ تجاوزت التارجت",IF(F11>=E11*0.8,"⚠️ قريب ("&TEXT(F11/E11,"0%")&")","❌ بعيد ("&TEXT(F11/E11,"0%")&")"))) -> — لم يبدأ
B12: يوليو | C12: =IFERROR('💸 المصروفات'!J21,0) -> 87850 | D12: 0.2 | E12: =IFERROR(D12/(1-E12),D12) -> 0.2 | F12: =IFERROR(يوليو!I104,0) -> 0 | G12: =E12-F12 -> 0.2 | H12: =IF(F12=0,"— لم يبدأ",IF(F12>=E12,"✅ تجاوزت التارجت",IF(F12>=E12*0.8,"⚠️ قريب ("&TEXT(F12/E12,"0%")&")","❌ بعيد ("&TEXT(F12/E12,"0%")&")"))) -> — لم يبدأ
B13: أغسطس | C13: =IFERROR('💸 المصروفات'!K21,0) -> 25900 | D13: 0.2 | E13: =IFERROR(D13/(1-E13),D13) -> 0.2 | F13: =IFERROR(أغسطس!I104,0) -> 0 | G13: =E13-F13 -> 0.2 | H13: =IF(F13=0,"— لم يبدأ",IF(F13>=E13,"✅ تجاوزت التارجت",IF(F13>=E13*0.8,"⚠️ قريب ("&TEXT(F13/E13,"0%")&")","❌ بعيد ("&TEXT(F13/E13,"0%")&")"))) -> — لم يبدأ
B14: سبتمبر | C14: =IFERROR('💸 المصروفات'!L21,0) -> 87850 | D14: 0.2 | E14: =IFERROR(D14/(1-E14),D14) -> 0.2 | F14: =IFERROR(سبتمبر!I104,0) -> 0 | G14: =E14-F14 -> 0.2 | H14: =IF(F14=0,"— لم يبدأ",IF(F14>=E14,"✅ تجاوزت التارجت",IF(F14>=E14*0.8,"⚠️ قريب ("&TEXT(F14/E14,"0%")&")","❌ بعيد ("&TEXT(F14/E14,"0%")&")"))) -> — لم يبدأ
B15: أكتوبر | C15: =IFERROR('💸 المصروفات'!M21,0) -> 87850 | D15: 0.2 | E15: =IFERROR(D15/(1-E15),D15) -> 0.2 | F15: =IFERROR(أكتوبر!I104,0) -> 0 | G15: =E15-F15 -> 0.2 | H15: =IF(F15=0,"— لم يبدأ",IF(F15>=E15,"✅ تجاوزت التارجت",IF(F15>=E15*0.8,"⚠️ قريب ("&TEXT(F15/E15,"0%")&")","❌ بعيد ("&TEXT(F15/E15,"0%")&")"))) -> — لم يبدأ
B16: نوفمبر | C16: =IFERROR('💸 المصروفات'!N21,0) -> 87850 | D16: 0.2 | E16: =IFERROR(D16/(1-E16),D16) -> 0.2 | F16: =IFERROR(نوفمبر!I104,0) -> 0 | G16: =E16-F16 -> 0.2 | H16: =IF(F16=0,"— لم يبدأ",IF(F16>=E16,"✅ تجاوزت التارجت",IF(F16>=E16*0.8,"⚠️ قريب ("&TEXT(F16/E16,"0%")&")","❌ بعيد ("&TEXT(F16/E16,"0%")&")"))) -> — لم يبدأ
B17: ديسمبر | C17: =IFERROR('💸 المصروفات'!O21,0) -> 87850 | D17: 0.2 | E17: =IFERROR(D17/(1-E17),D17) -> 0.2 | F17: =IFERROR(ديسمبر!I104,0) -> 0 | G17: =E17-F17 -> 0.2 | H17: =IF(F17=0,"— لم يبدأ",IF(F17>=E17,"✅ تجاوزت التارجت",IF(F17>=E17*0.8,"⚠️ قريب ("&TEXT(F17/E17,"0%")&")","❌ بعيد ("&TEXT(F17/E17,"0%")&")"))) -> — لم يبدأ
B18: إجمالي السنة | C18: =SUM(D6:D17) -> 2.4 | E18: =SUM(F6:F17) -> 0 | F18: =SUM(G6:G17) -> 2.4 | G18: =SUM(G6:G17) -> 2.4 | H18: =IF(F18>=E18,"✅ سنة رابحة","❌ محتاج تحسين") -> ✅ سنة رابحة
B20: ▶ اقتراحات ذكية – إزاي توصل للتارجت لكل شهر
B21: اختر الشهر للاقتراحات | D21: يناير | E21: 💡 الاقتراحات بتتغير تلقائياً حسب الشهر المختار والمصروفات المدخلة
B22: إجمالي المصروفات | C22: =IFERROR(INDEX(D6:D17,MATCH($D$21,{"يناير","فبراير","مارس","أبريل","مايو","يونيو","يوليو","أغسطس","سبتمبر","أكتوبر","نوفمبر","ديسمبر"},0)),0) -> 0.2 | D22: نسبة الربح | E22: =IFERROR(INDEX(E6:E17,MATCH($D$21,{"يناير","فبراير","مارس","أبريل","مايو","يونيو","يوليو","أغسطس","سبتمبر","أكتوبر","نوفمبر","ديسمبر"},0)),0) -> 0.2 | F22: التارجت المطلوب | G22: =IFERROR(INDEX(F6:F17,MATCH($D$21,{"يناير","فبراير","مارس","أبريل","مايو","يونيو","يوليو","أغسطس","سبتمبر","أكتوبر","نوفمبر","ديسمبر"},0)),0) -> 0 | H22: المحصّل حتى الآن | I22: =IFERROR(INDEX(G6:G17,MATCH($D$21,{"يناير","فبراير","مارس","أبريل","مايو","يونيو","يوليو","أغسطس","سبتمبر","أكتوبر","نوفمبر","ديسمبر"},0)),0) -> 0.2
B24: الخدمة | C24: الوحدة | D24: السعر (ج.م) | E24: وحدات للتارجت وحدها | F24: إيراد 50 وحدة | G24: إيراد 30 وحدة | H24: تغطية 50 | I24: تغطية 30
B25: 🏫 حضانة | C25: بالشهر | D25: ='⚙️ الإعدادات'!E5 -> 3500 | E25: =IFERROR(CEILING(IFERROR(INDEX(F6:F17,MATCH($D$21,{"يناير","فبراير","مارس","أبريل","مايو","يونيو","يوليو","أغسطس","سبتمبر","أكتوبر","نوفمبر","ديسمبر"},0)),1)/'⚙️ الإعدادات'!E5,1),0) -> 0 | F25: =50*'⚙️ الإعدادات'!E5 -> 175000 | G25: =30*'⚙️ الإعدادات'!E5 -> 105000 | H25: =IFERROR(50*'⚙️ الإعدادات'!E5/IFERROR(INDEX(F6:F17,MATCH($D$21,{"يناير","فبراير","مارس","أبريل","مايو","يونيو","يوليو","أغسطس","سبتمبر","أكتوبر","نوفمبر","ديسمبر"},0)),1),0) -> 0 | I25: =IFERROR(30*'⚙️ الإعدادات'!E5/IFERROR(INDEX(F6:F17,MATCH($D$21,{"يناير","فبراير","مارس","أبريل","مايو","يونيو","يوليو","أغسطس","سبتمبر","أكتوبر","نوفمبر","ديسمبر"},0)),1),0) -> 0
B26: 🏫 حضانة | C26: باليوم | D26: ='⚙️ الإعدادات'!D5 -> 200 | E26: =IFERROR(CEILING(IFERROR(INDEX(F6:F17,MATCH($D$21,{"يناير","فبراير","مارس","أبريل","مايو","يونيو","يوليو","أغسطس","سبتمبر","أكتوبر","نوفمبر","ديسمبر"},0)),1)/'⚙️ الإعدادات'!D5,1),0) -> 0 | F26: =50*'⚙️ الإعدادات'!D5 -> 10000 | G26: =30*'⚙️ الإعدادات'!D5 -> 6000 | H26: =IFERROR(50*'⚙️ الإعدادات'!D5/IFERROR(INDEX(F6:F17,MATCH($D$21,{"يناير","فبراير","مارس","أبريل","مايو","يونيو","يوليو","أغسطس","سبتمبر","أكتوبر","نوفمبر","ديسمبر"},0)),1),0) -> 0 | I26: =IFERROR(30*'⚙️ الإعدادات'!D5/IFERROR(INDEX(F6:F17,MATCH($D$21,{"يناير","فبراير","مارس","أبريل","مايو","يونيو","يوليو","أغسطس","سبتمبر","أكتوبر","نوفمبر","ديسمبر"},0)),1),0) -> 0
B27: 🏫 حضانة | C27: بالساعة | D27: ='⚙️ الإعدادات'!C5 -> 50 | E27: =IFERROR(CEILING(IFERROR(INDEX(F6:F17,MATCH($D$21,{"يناير","فبراير","مارس","أبريل","مايو","يونيو","يوليو","أغسطس","سبتمبر","أكتوبر","نوفمبر","ديسمبر"},0)),1)/'⚙️ الإعدادات'!C5,1),0) -> 0 | F27: =50*'⚙️ الإعدادات'!C5 -> 2500 | G27: =30*'⚙️ الإعدادات'!C5 -> 1500 | H27: =IFERROR(50*'⚙️ الإعدادات'!C5/IFERROR(INDEX(F6:F17,MATCH($D$21,{"يناير","فبراير","مارس","أبريل","مايو","يونيو","يوليو","أغسطس","سبتمبر","أكتوبر","نوفمبر","ديسمبر"},0)),1),0) -> 0 | I27: =IFERROR(30*'⚙️ الإعدادات'!C5/IFERROR(INDEX(F6:F17,MATCH($D$21,{"يناير","فبراير","مارس","أبريل","مايو","يونيو","يوليو","أغسطس","سبتمبر","أكتوبر","نوفمبر","ديسمبر"},0)),1),0) -> 0
B28: 🏠 استضافة | C28: بالشهر | D28: ='⚙️ الإعدادات'!E6 -> 2500 | E28: =IFERROR(CEILING(IFERROR(INDEX(F6:F17,MATCH($D$21,{"يناير","فبراير","مارس","أبريل","مايو","يونيو","يوليو","أغسطس","سبتمبر","أكتوبر","نوفمبر","ديسمبر"},0)),1)/'⚙️ الإعدادات'!E6,1),0) -> 0 | F28: =50*'⚙️ الإعدادات'!E6 -> 125000 | G28: =30*'⚙️ الإعدادات'!E6 -> 75000 | H28: =IFERROR(50*'⚙️ الإعدادات'!E6/IFERROR(INDEX(F6:F17,MATCH($D$21,{"يناير","فبراير","مارس","أبريل","مايو","يونيو","يوليو","أغسطس","سبتمبر","أكتوبر","نوفمبر","ديسمبر"},0)),1),0) -> 0 | I28: =IFERROR(30*'⚙️ الإعدادات'!E6/IFERROR(INDEX(F6:F17,MATCH($D$21,{"يناير","فبراير","مارس","أبريل","مايو","يونيو","يوليو","أغسطس","سبتمبر","أكتوبر","نوفمبر","ديسمبر"},0)),1),0) -> 0
B29: 🏠 استضافة | C29: باليوم | D29: ='⚙️ الإعدادات'!D6 -> 150 | E29: =IFERROR(CEILING(IFERROR(INDEX(F6:F17,MATCH($D$21,{"يناير","فبراير","مارس","أبريل","مايو","يونيو","يوليو","أغسطس","سبتمبر","أكتوبر","نوفمبر","ديسمبر"},0)),1)/'⚙️ الإعدادات'!D6,1),0) -> 0 | F29: =50*'⚙️ الإعدادات'!D6 -> 7500 | G29: =30*'⚙️ الإعدادات'!D6 -> 4500 | H29: =IFERROR(50*'⚙️ الإعدادات'!D6/IFERROR(INDEX(F6:F17,MATCH($D$21,{"يناير","فبراير","مارس","أبريل","مايو","يونيو","يوليو","أغسطس","سبتمبر","أكتوبر","نوفمبر","ديسمبر"},0)),1),0) -> 0 | I29: =IFERROR(30*'⚙️ الإعدادات'!D6/IFERROR(INDEX(F6:F17,MATCH($D$21,{"يناير","فبراير","مارس","أبريل","مايو","يونيو","يوليو","أغسطس","سبتمبر","أكتوبر","نوفمبر","ديسمبر"},0)),1),0) -> 0
B30: 🏠 استضافة | C30: بالساعة | D30: ='⚙️ الإعدادات'!C6 -> 40 | E30: =IFERROR(CEILING(IFERROR(INDEX(F6:F17,MATCH($D$21,{"يناير","فبراير","مارس","أبريل","مايو","يونيو","يوليو","أغسطس","سبتمبر","أكتوبر","نوفمبر","ديسمبر"},0)),1)/'⚙️ الإعدادات'!C6,1),0) -> 0 | F30: =50*'⚙️ الإعدادات'!C6 -> 2000 | G30: =30*'⚙️ الإعدادات'!C6 -> 1200 | H30: =IFERROR(50*'⚙️ الإعدادات'!C6/IFERROR(INDEX(F6:F17,MATCH($D$21,{"يناير","فبراير","مارس","أبريل","مايو","يونيو","يوليو","أغسطس","سبتمبر","أكتوبر","نوفمبر","ديسمبر"},0)),1),0) -> 0 | I30: =IFERROR(30*'⚙️ الإعدادات'!C6/IFERROR(INDEX(F6:F17,MATCH($D$21,{"يناير","فبراير","مارس","أبريل","مايو","يونيو","يوليو","أغسطس","سبتمبر","أكتوبر","نوفمبر","ديسمبر"},0)),1),0) -> 0
B31: 🩺 جلسة | C31: بالساعة | D31: ='⚙️ الإعدادات'!C7 -> 200 | E31: =IFERROR(CEILING(IFERROR(INDEX(F6:F17,MATCH($D$21,{"يناير","فبراير","مارس","أبريل","مايو","يونيو","يوليو","أغسطس","سبتمبر","أكتوبر","نوفمبر","ديسمبر"},0)),1)/'⚙️ الإعدادات'!C7,1),0) -> 0 | F31: =50*'⚙️ الإعدادات'!C7 -> 10000 | G31: =30*'⚙️ الإعدادات'!C7 -> 6000 | H31: =IFERROR(50*'⚙️ الإعدادات'!C7/IFERROR(INDEX(F6:F17,MATCH($D$21,{"يناير","فبراير","مارس","أبريل","مايو","يونيو","يوليو","أغسطس","سبتمبر","أكتوبر","نوفمبر","ديسمبر"},0)),1),0) -> 0 | I31: =IFERROR(30*'⚙️ الإعدادات'!C7/IFERROR(INDEX(F6:F17,MATCH($D$21,{"يناير","فبراير","مارس","أبريل","مايو","يونيو","يوليو","أغسطس","سبتمبر","أكتوبر","نوفمبر","ديسمبر"},0)),1),0) -> 0
B32: 🩺 جلسة | C32: باليوم | D32: ='⚙️ الإعدادات'!D7 -> 600 | E32: =IFERROR(CEILING(IFERROR(INDEX(F6:F17,MATCH($D$21,{"يناير","فبراير","مارس","أبريل","مايو","يونيو","يوليو","أغسطس","سبتمبر","أكتوبر","نوفمبر","ديسمبر"},0)),1)/'⚙️ الإعدادات'!D7,1),0) -> 0 | F32: =50*'⚙️ الإعدادات'!D7 -> 30000 | G32: =30*'⚙️ الإعدادات'!D7 -> 18000 | H32: =IFERROR(50*'⚙️ الإعدادات'!D7/IFERROR(INDEX(F6:F17,MATCH($D$21,{"يناير","فبراير","مارس","أبريل","مايو","يونيو","يوليو","أغسطس","سبتمبر","أكتوبر","نوفمبر","ديسمبر"},0)),1),0) -> 0 | I32: =IFERROR(30*'⚙️ الإعدادات'!D7/IFERROR(INDEX(F6:F17,MATCH($D$21,{"يناير","فبراير","مارس","أبريل","مايو","يونيو","يوليو","أغسطس","سبتمبر","أكتوبر","نوفمبر","ديسمبر"},0)),1),0) -> 0
B34: ▶ حاسبة التوزيع المخصص – جرّب أي تركيبة وشوف هل بتوصل للتارجت
B35: 📝 أدخل الأعداد المتوقعة في الخانات الصفراء — النتيجة بتتحسب تلقائياً مع الإشارة للتارجت
B36: الخدمة | C36: الوحدة | D36: السعر (ج.م) | E36: العدد / الكمية ← اكتب هنا | F36: الإيراد المتوقع (ج.م)
B37: 🏫 حضانة | C37: بالشهر | D37: ='⚙️ الإعدادات'!E5 -> 3500 | E37: 0 | F37: =E37*D37 -> 0
B38: 🏫 حضانة | C38: باليوم | D38: ='⚙️ الإعدادات'!D5 -> 200 | E38: 0 | F38: =E38*D38 -> 0
B39: 🏫 حضانة | C39: بالساعة | D39: ='⚙️ الإعدادات'!C5 -> 50 | E39: 0 | F39: =E39*D39 -> 0
B40: 🏠 استضافة | C40: بالشهر | D40: ='⚙️ الإعدادات'!E6 -> 2500 | E40: 0 | F40: =E40*D40 -> 0
B41: 🏠 استضافة | C41: باليوم | D41: ='⚙️ الإعدادات'!D6 -> 150 | E41: 0 | F41: =E41*D41 -> 0
B42: 🏠 استضافة | C42: بالساعة | D42: ='⚙️ الإعدادات'!C6 -> 40 | E42: 0 | F42: =E42*D42 -> 0
B43: 🩺 جلسة | C43: بالساعة | D43: ='⚙️ الإعدادات'!C7 -> 200 | E43: 0 | F43: =E43*D43 -> 0
B44: 🩺 جلسة | C44: باليوم | D44: ='⚙️ الإعدادات'!D7 -> 600 | E44: 0 | F44: =E44*D44 -> 0
B45: إجمالي الإيراد المتوقع من التوزيع | F45: =SUM(F37:F44) -> 0
...

Sheet يناير
B1: 📅 يناير – متابعة إيرادات الأطفال
B3: # | C3: اسم الطفل | D3: الخدمة | E3: الوحدة | F3: الكمية | G3: السعر (ج.م) | H3: الإجمالي (ج.م) | I3: المدفوع (ج.م) | J3: الرصيد (ج.م) | K3: الحالة | L3: ملاحظات
B4: 1 | C4: ='👶 بيانات الأطفال'!C4 -> أحمد محمد | D4: حضانة | E4: شهر | F4: 1 | G4: 3500 | H4: =IFERROR(F4*G4,0) -> 3500 | J4: =H4-IFERROR(I4,0) -> 3500 | K4: =IF(IFERROR(I4,0)=0,"❌ لم يُدفع",IF(I4>=H4,"✅ مدفوع","⚠️ جزئي")) -> ❌ لم يُدفع
B5: 2 | C5: ='👶 بيانات الأطفال'!C5 -> فاطمة علي | D5: حضانة | E5: شهر | F5: 1 | G5: 3500 | H5: =IFERROR(F5*G5,0) -> 3500 | J5: =H5-IFERROR(I5,0) -> 3500 | K5: =IF(IFERROR(I5,0)=0,"❌ لم يُدفع",IF(I5>=H5,"✅ مدفوع","⚠️ جزئي")) -> ❌ لم يُدفع
B6: 3 | C6: ='👶 بيانات الأطفال'!C6 -> عمر خالد | D6: جلسة | E6: جلسة | F6: 0 | G6: 800 | H6: =IFERROR(F6*G6,0) -> 0 | J6: =H6-IFERROR(I6,0) -> 0 | K6: =IF(IFERROR(I6,0)=0,"❌ لم يُدفع",IF(I6>=H6,"✅ مدفوع","⚠️ جزئي")) -> ❌ لم يُدفع
B7: 4 | C7: ='👶 بيانات الأطفال'!C7 -> نور السيد | D7: استضافة | E7: يوم | F7: 0 | G7: 200 | H7: =IFERROR(F7*G7,0) -> 0 | J7: =H7-IFERROR(I7,0) -> 0 | K7: =IF(IFERROR(I7,0)=0,"❌ لم يُدفع",IF(I7>=H7,"✅ مدفوع","⚠️ جزئي")) -> ❌ لم يُدفع
B8: 5 | C8: ='👶 بيانات الأطفال'!C8 -> مريم إبراهيم | D8: حضانة | E8: شهر | F8: 1 | G8: 3500 | H8: =IFERROR(F8*G8,0) -> 3500 | J8: =H8-IFERROR(I8,0) -> 3500 | K8: =IF(IFERROR(I8,0)=0,"❌ لم يُدفع",IF(I8>=H8,"✅ مدفوع","⚠️ جزئي")) -> ❌ لم يُدفع
B9: 6 | C9: ='👶 بيانات الأطفال'!C9 -> يوسف حسن | D9: جلسة | E9: جلسة | F9: 0 | G9: 800 | H9: =IFERROR(F9*G9,0) -> 0 | J9: =H9-IFERROR(I9,0) -> 0 | K9: =IF(IFERROR(I9,0)=0,"❌ لم يُدفع",IF(I9>=H9,"✅ مدفوع","⚠️ جزئي")) -> ❌ لم يُدفع
B10: 7 | C10: ='👶 بيانات الأطفال'!C10 -> سارة أحمد | D10: حضانة | E10: شهر | F10: 1 | G10: 3500 | H10: =IFERROR(F10*G10,0) -> 3500 | J10: =H10-IFERROR(I10,0) -> 3500 | K10: =IF(IFERROR(I10,0)=0,"❌ لم يُدفع",IF(I10>=H10,"✅ مدفوع","⚠️ جزئي")) -> ❌ لم يُدفع
B11: 8 | C11: ='👶 بيانات الأطفال'!C11 -> كريم محمود | D11: استضافة | E11: يوم | F11: 0 | G11: 200 | H11: =IFERROR(F11*G11,0) -> 0 | J11: =H11-IFERROR(I11,0) -> 0 | K11: =IF(IFERROR(I11,0)=0,"❌ لم يُدفع",IF(I11>=H11,"✅ مدفوع","⚠️ جزئي")) -> ❌ لم يُدفع
B12: 9 | C12: ='👶 بيانات الأطفال'!C12 -> لينا طارق | D12: حضانة | E12: شهر | F12: 1 | G12: 3500 | H12: =IFERROR(F12*G12,0) -> 3500 | J12: =H12-IFERROR(I12,0) -> 3500 | K12: =IF(IFERROR(I12,0)=0,"❌ لم يُدفع",IF(I12>=H12,"✅ مدفوع","⚠️ جزئي")) -> ❌ لم يُدفع
B13: 10 | C13: ='👶 بيانات الأطفال'!C13 -> جنى وليد | D13: جلسة | E13: جلسة | F13: 0 | G13: 800 | H13: =IFERROR(F13*G13,0) -> 0 | J13: =H13-IFERROR(I13,0) -> 0 | K13: =IF(IFERROR(I13,0)=0,"❌ لم يُدفع",IF(I13>=H13,"✅ مدفوع","⚠️ جزئي")) -> ❌ لم يُدفع
B14: 11 | C14: ='👶 بيانات الأطفال'!C14 -> زياد عمر | D14: حضانة | E14: شهر | F14: 1 | G14: 3500 | H14: =IFERROR(F14*G14,0) -> 3500 | J14: =H14-IFERROR(I14,0) -> 3500 | K14: =IF(IFERROR(I14,0)=0,"❌ لم يُدفع",IF(I14>=H14,"✅ مدفوع","⚠️ جزئي")) -> ❌ لم يُدفع
B15: 12 | C15: ='👶 بيانات الأطفال'!C15 -> ريم ناصر | D15: حضانة | E15: شهر | F15: 1 | G15: 3500 | H15: =IFERROR(F15*G15,0) -> 3500 | J15: =H15-IFERROR(I15,0) -> 3500 | K15: =IF(IFERROR(I15,0)=0,"❌ لم يُدفع",IF(I15>=H15,"✅ مدفوع","⚠️ جزئي")) -> ❌ لم يُدفع
... B103: 100 | C103: ='👶 بيانات الأطفال'!C103 -> حسن علاء 100 | D103: جلسة | E103: جلسة | F103: 0 | G103: 800 | H103: =IFERROR(F103*G103,0) -> 0 | J103: =H103-IFERROR(I103,0) -> 0 | K103: =IF(IFERROR(I103,0)=0,"❌ لم يُدفع",IF(I103>=H103,"✅ مدفوع","⚠️ جزئي")) -> ❌ لم يُدفع
B104: ◀ إجمالي الشهر | H104: =SUM(H4:H103) -> 175000 | I104: =SUM(I4:I103) -> 0 | J104: =SUM(J4:J103) -> 175000 | K104: =COUNTIF(K4:K103,"✅ مدفوع")&" ✅ | "&COUNTIF(K4:K103,"❌ لم يُدفع")&" ❌" -> 0 ✅ | 100 ❌
B106: ▶ 📊 ملخص الشهر الفوري
B107: 💰 إجمالي الفواتير | H107: =H104 -> 175000
B108: ✅ المحصّل | H108: =I104 -> 0
B109: 💸 مصروفات تشغيلية | H109: =IFERROR('💸 المصروفات'!D20,0) -> 25900
B110: 👔 رواتب الشهر | H110: =IFERROR('👔 الرواتب'!L15,0) -> 61950
B111: 📊 إجمالي المصروفات | H111: =IFERROR('💸 المصروفات'!D21,0) -> 25900
B112: 📈 صافي الربح | H112: =I104-IFERROR('💸 المصروفات'!D21,0) -> -25900
B113: 🎯 التارجت المطلوب | H113: =IFERROR('💸 المصروفات'!D21/(1-'⚙️ الإعدادات'!C7),0) -> -130.15075
B114: 📊 نسبة التحصيل | H114: =IFERROR(I104/H104,0) -> 0

Sheet فبراير
B1: 📅 فبراير – متابعة إيرادات الأطفال
B3: # | C3: اسم الطفل | D3: الخدمة | E3: الوحدة | F3: الكمية | G3: السعر (ج.م) | H3: الإجمالي (ج.م) | I3: المدفوع (ج.م) | J3: الرصيد (ج.م) | K3: الحالة | L3: ملاحظات
B4: 1 | C4: ='👶 بيانات الأطفال'!C4 -> أحمد محمد | D4: حضانة | E4: شهر | F4: 1 | G4: 3500 | H4: =IFERROR(F4*G4,0) -> 3500 | J4: =H4-IFERROR(I4,0) -> 3500 | K4: =IF(IFERROR(I4,0)=0,"❌ لم يُدفع",IF(I4>=H4,"✅ مدفوع","⚠️ جزئي")) -> ❌ لم يُدفع
B5: 2 | C5: ='👶 بيانات الأطفال'!C5 -> فاطمة علي | D5: حضانة | E5: شهر | F5: 1 | G5: 3500 | H5: =IFERROR(F5*G5,0) -> 3500 | J5: =H5-IFERROR(I5,0) -> 3500 | K5: =IF(IFERROR(I5,0)=0,"❌ لم يُدفع",IF(I5>=H5,"✅ مدفوع","⚠️ جزئي")) -> ❌ لم يُدفع
B6: 3 | C6: ='👶 بيانات الأطفال'!C6 -> عمر خالد | D6: جلسة | E6: جلسة | F6: 0 | G6: 800 | H6: =IFERROR(F6*G6,0) -> 0 | J6: =H6-IFERROR(I6,0) -> 0 | K6: =IF(IFERROR(I6,0)=0,"❌ لم يُدفع",IF(I6>=H6,"✅ مدفوع","⚠️ جزئي")) -> ❌ لم يُدفع
B7: 4 | C7: ='👶 بيانات الأطفال'!C7 -> نور السيد | D7: استضافة | E7: يوم | F7: 0 | G7: 200 | H7: =IFERROR(F7*G7,0) -> 0 | J7: =H7-IFERROR(I7,0) -> 0 | K7: =IF(IFERROR(I7,0)=0,"❌ لم يُدفع",IF(I7>=H7,"✅ مدفوع","⚠️ جزئي")) -> ❌ لم يُدفع
B8: 5 | C8: ='👶 بيانات الأطفال'!C8 -> مريم إبراهيم | D8: حضانة | E8: شهر | F8: 1 | G8: 3500 | H8: =IFERROR(F8*G8,0) -> 3500 | J8: =H8-IFERROR(I8,0) -> 3500 | K8: =IF(IFERROR(I8,0)=0,"❌ لم يُدفع",IF(I8>=H8,"✅ مدفوع","⚠️ جزئي")) -> ❌ لم يُدفع
B9: 6 | C9: ='👶 بيانات الأطفال'!C9 -> يوسف حسن | D9: جلسة | E9: جلسة | F9: 0 | G9: 800 | H9: =IFERROR(F9*G9,0) -> 0 | J9: =H9-IFERROR(I9,0) -> 0 | K9: =IF(IFERROR(I9,0)=0,"❌ لم يُدفع",IF(I9>=H9,"✅ مدفوع","⚠️ جزئي")) -> ❌ لم يُدفع
B10: 7 | C10: ='👶 بيانات الأطفال'!C10 -> سارة أحمد | D10: حضانة | E10: شهر | F10: 1 | G10: 3500 | H10: =IFERROR(F10*G10,0) -> 3500 | J10: =H10-IFERROR(I10,0) -> 3500 | K10: =IF(IFERROR(I10,0)=0,"❌ لم يُدفع",IF(I10>=H10,"✅ مدفوع","⚠️ جزئي")) -> ❌ لم يُدفع
B11: 8 | C11: ='👶 بيانات الأطفال'!C11 -> كريم محمود | D11: استضافة | E11: يوم | F11: 0 | G11: 200 | H11: =IFERROR(F11*G11,0) -> 0 | J11: =H11-IFERROR(I11,0) -> 0 | K11: =IF(IFERROR(I11,0)=0,"❌ لم يُدفع",IF(I11>=H11,"✅ مدفوع","⚠️ جزئي")) -> ❌ لم يُدفع
B12: 9 | C12: ='👶 بيانات الأطفال'!C12 -> لينا طارق | D12: حضانة | E12: شهر | F12: 1 | G12: 3500 | H12: =IFERROR(F12*G12,0) -> 3500 | J12: =H12-IFERROR(I12,0) -> 3500 | K12: =IF(IFERROR(I12,0)=0,"❌ لم يُدفع",IF(I12>=H12,"✅ مدفوع","⚠️ جزئي")) -> ❌ لم يُدفع
B13: 10 | C13: ='👶 بيانات الأطفال'!C13 -> جنى وليد | D13: جلسة | E13: جلسة | F13: 0 | G13: 800 | H13: =IFERROR(F13*G13,0) -> 0 | J13: =H13-IFERROR(I13,0) -> 0 | K13: =IF(IFERROR(I13,0)=0,"❌ لم يُدفع",IF(I13>=H13,"✅ مدفوع","⚠️ جزئي")) -> ❌ لم يُدفع
B14: 11 | C14: ='👶 بيانات الأطفال'!C14 -> زياد عمر | D14: حضانة | E14: شهر | F14: 1 | G14: 3500 | H14: =IFERROR(F14*G14,0) -> 3500 | J14: =H14-IFERROR(I14,0) -> 3500 | K14: =IF(IFERROR(I14,0)=0,"❌ لم يُدفع",IF(I14>=H14,"✅ مدفوع","⚠️ جزئي")) -> ❌ لم يُدفع
B15: 12 | C15: ='👶 بيانات الأطفال'!C15 -> ريم ناصر | D15: حضانة | E15: شهر | F15: 1 | G15: 3500 | H15: =IFERROR(F15*G15,0) -> 3500 | J15: =H15-IFERROR(I15,0) -> 3500 | K15: =IF(IFERROR(I15,0)=0,"❌ لم يُدفع",IF(I15>=H15,"✅ مدفوع","⚠️ جزئي")) -> ❌ لم يُدفع
... B103: 100 | C103: ='👶 بيانات الأطفال'!C103 -> حسن علاء 100 | D103: جلسة | E103: جلسة | F103: 0 | G103: 800 | H103: =IFERROR(F103*G103,0) -> 0 | J103: =H103-IFERROR(I103,0) -> 0 | K103: =IF(IFERROR(I103,0)=0,"❌ لم يُدفع",IF(I103>=H103,"✅ مدفوع","⚠️ جزئي")) -> ❌ لم يُدفع
B104: ◀ إجمالي الشهر | H104: =SUM(H4:H103) -> 175000 | I104: =SUM(I4:I103) -> 0 | J104: =SUM(J4:J103) -> 175000 | K104: =COUNTIF(K4:K103,"✅ مدفوع")&" ✅ | "&COUNTIF(K4:K103,"❌ لم يُدفع")&" ❌" -> 0 ✅ | 100 ❌
B106: ▶ 📊 ملخص الشهر الفوري
B107: 💰 إجمالي الفواتير | H107: =H104 -> 175000
B108: ✅ المحصّل | H108: =I104 -> 0
B109: 💸 مصروفات تشغيلية | H109: =IFERROR('💸 المصروفات'!E20,0) -> 25900
B110: 👔 رواتب الشهر | H110: =IFERROR('👔 الرواتب'!M15,0) -> 61950
B111: 📊 إجمالي المصروفات | H111: =IFERROR('💸 المصروفات'!E21,0) -> 81900
B112: 📈 صافي الربح | H112: =I104-IFERROR('💸 المصروفات'!E21,0) -> -81900
B113: 🎯 التارجت المطلوب | H113: =IFERROR('💸 المصروفات'!E21/(1-'⚙️ الإعدادات'!C7),0) -> -411.55779
B114: 📊 نسبة التحصيل | H114: =IFERROR(I104/H104,0) -> 0

Sheet مارس
B1: 📅 مارس – متابعة إيرادات الأطفال
B3: # | C3: اسم الطفل | D3: الخدمة | E3: الوحدة | F3: الكمية | G3: السعر (ج.م) | H3: الإجمالي (ج.م) | I3: المدفوع (ج.م) | J3: الرصيد (ج.م) | K3: الحالة | L3: ملاحظات
B4: 1 | C4: ='👶 بيانات الأطفال'!C4 -> أحمد محمد | D4: حضانة | E4: شهر | F4: 1 | G4: 3500 | H4: =IFERROR(F4*G4,0) -> 3500 | J4: =H4-IFERROR(I4,0) -> 3500 | K4: =IF(IFERROR(I4,0)=0,"❌ لم يُدفع",IF(I4>=H4,"✅ مدفوع","⚠️ جزئي")) -> ❌ لم يُدفع
B5: 2 | C5: ='👶 بيانات الأطفال'!C5 -> فاطمة علي | D5: حضانة | E5: شهر | F5: 1 | G5: 3500 | H5: =IFERROR(F5*G5,0) -> 3500 | J5: =H5-IFERROR(I5,0) -> 3500 | K5: =IF(IFERROR(I5,0)=0,"❌ لم يُدفع",IF(I5>=H5,"✅ مدفوع","⚠️ جزئي")) -> ❌ لم يُدفع
B6: 3 | C6: ='👶 بيانات الأطفال'!C6 -> عمر خالد | D6: جلسة | E6: جلسة | F6: 0 | G6: 800 | H6: =IFERROR(F6*G6,0) -> 0 | J6: =H6-IFERROR(I6,0) -> 0 | K6: =IF(IFERROR(I6,0)=0,"❌ لم يُدفع",IF(I6>=H6,"✅ مدفوع","⚠️ جزئي")) -> ❌ لم يُدفع
B7: 4 | C7: ='👶 بيانات الأطفال'!C7 -> نور السيد | D7: استضافة | E7: يوم | F7: 0 | G7: 200 | H7: =IFERROR(F7*G7,0) -> 0 | J7: =H7-IFERROR(I7,0) -> 0 | K7: =IF(IFERROR(I7,0)=0,"❌ لم يُدفع",IF(I7>=H7,"✅ مدفوع","⚠️ جزئي")) -> ❌ لم يُدفع
B8: 5 | C8: ='👶 بيانات الأطفال'!C8 -> مريم إبراهيم | D8: حضانة | E8: شهر | F8: 1 | G8: 3500 | H8: =IFERROR(F8*G8,0) -> 3500 | J8: =H8-IFERROR(I8,0) -> 3500 | K8: =IF(IFERROR(I8,0)=0,"❌ لم يُدفع",IF(I8>=H8,"✅ مدفوع","⚠️ جزئي")) -> ❌ لم يُدفع
B9: 6 | C9: ='👶 بيانات الأطفال'!C9 -> يوسف حسن | D9: جلسة | E9: جلسة | F9: 0 | G9: 800 | H9: =IFERROR(F9*G9,0) -> 0 | J9: =H9-IFERROR(I9,0) -> 0 | K9: =IF(IFERROR(I9,0)=0,"❌ لم يُدفع",IF(I9>=H9,"✅ مدفوع","⚠️ جزئي")) -> ❌ لم يُدفع
B10: 7 | C10: ='👶 بيانات الأطفال'!C10 -> سارة أحمد | D10: حضانة | E10: شهر | F10: 1 | G10: 3500 | H10: =IFERROR(F10*G10,0) -> 3500 | J10: =H10-IFERROR(I10,0) -> 3500 | K10: =IF(IFERROR(I10,0)=0,"❌ لم يُدفع",IF(I10>=H10,"✅ مدفوع","⚠️ جزئي")) -> ❌ لم يُدفع
B11: 8 | C11: ='👶 بيانات الأطفال'!C11 -> كريم محمود | D11: استضافة | E11: يوم | F11: 0 | G11: 200 | H11: =IFERROR(F11*G11,0) -> 0 | J11: =H11-IFERROR(I11,0) -> 0 | K11: =IF(IFERROR(I11,0)=0,"❌ لم يُدفع",IF(I11>=H11,"✅ مدفوع","⚠️ جزئي")) -> ❌ لم يُدفع
B12: 9 | C12: ='👶 بيانات الأطفال'!C12 -> لينا طارق | D12: حضانة | E12: شهر | F12: 1 | G12: 3500 | H12: =IFERROR(F12*G12,0) -> 3500 | J12: =H12-IFERROR(I12,0) -> 3500 | K12: =IF(IFERROR(I12,0)=0,"❌ لم يُدفع",IF(I12>=H12,"✅ مدفوع","⚠️ جزئي")) -> ❌ لم يُدفع
B13: 10 | C13: ='👶 بيانات الأطفال'!C13 -> جنى وليد | D13: جلسة | E13: جلسة | F13: 0 | G13: 800 | H13: =IFERROR(F13*G13,0) -> 0 | J13: =H13-IFERROR(I13,0) -> 0 | K13: =IF(IFERROR(I13,0)=0,"❌ لم يُدفع",IF(I13>=H13,"✅ مدفوع","⚠️ جزئي")) -> ❌ لم يُدفع
B14: 11 | C14: ='👶 بيانات الأطفال'!C14 -> زياد عمر | D14: حضانة | E14: شهر | F14: 1 | G14: 3500 | H14: =IFERROR(F14*G14,0) -> 3500 | J14: =H14-IFERROR(I14,0) -> 3500 | K14: =IF(IFERROR(I14,0)=0,"❌ لم يُدفع",IF(I14>=H14,"✅ مدفوع","⚠️ جزئي")) -> ❌ لم يُدفع
